Workbook

Sheet Data
A1: Grupo planificación | B1: Clase de orden | C1: Clase actividad PM | D1: Aviso | E1: Orden | F1: Grupo planificación | G1: Texto breve | H1: Pto.tbjo.responsable | I1: Ubicación técnica | J1: Denom.ubic.técnica | K1: Status de sistema | L1: Status de usuario | M1: Fecha inicio extrema | N1: Fecha fin extrema | O1: Autor | P1: Modificado por | Q1: Fecha liber.real | R1: Fecha de creación | S1: Inicio programado | T1: Fecha inicio real | U1: Fecha fin real | V1: Plan mant.preventivo | W1: Posición mantenim. | X1: Costes tot.reales | Y1: Tota general (plan)
A2: C81 | B2: PL | C2: 025 | D2: 30000012 | E2: 110475425 | F2: C81 | G2: 48M MTTO COMPRESOR 08 | H2: CGSTMRMM | I2: CHSS-SU-CTS-A90-COS08 | J2: COMPRESOR CENTRIFUGO ELLIOTT 08 | K2: CTEC NOTI DOCU IMOP JBFI KKMP PREC PROG | L2: TBTR | M2: 46153 | N2: 46157 | O2: VVERG011 | P2: AAGUI058 | Q2: 46145 | R2: 46140 | S2: 46153 | T2: 46153 | U2: 46165 | X2: 2494.34 | Y2: 2494.34
A3: C81 | B3: NP | C3: 035 | D3: 30042953 | E3: 110522634 | F3: C81 | G3: visor de aceite sucio y bajo nivel | H3: CGSTMRMM | I3: CHSS-SU-CTS-A90-COS12-SLU | J3: SISTEMA DE LUBRICACIÓN | K3: CTEC NOTI DOCU IMOP JBFI KKMP PREC | L3: TBTR | M3: 46157 | N3: 46157 | O3: MCHAV005 | P3: AAGUI058 | Q3: 46157 | R3: 46155 | S3: 46157 | T3: 46157 | U3: 46162 | X3: 445.3 | Y3: 445.3
A4: C81 | B4: PL | C4: 025 | D4: 28514171 | E4: 109037159 | F4: C81 | G4: Cambio de calefactor de aceite Comp N°1 | H4: CGSTMRMM | I4: CHSS-SU-CTS-A90-COS01-SLU-CALF | J4: CALEFACTOR DE ACEITE | K4: CTEC NOTI DOCU IMOP JBFI MACO MOVM PREC* | L4: TBTR | M4: 46160 | N4: 46160 | O4: TRAMI002 | P4: AAGUI058 | Q4: 45680 | R4: 45679 | S4: 46160 | T4: 46160 | U4: 46166 | X4: 6629.26 | Y4: 6629.25
A5: C81 | B5: PL | C5: 025 | D5: 28653199 | E5: 109170171 | F5: C81 | G5: COMP 8 CAMBIO VALVULAS AD/VE (ACT) | H5: CGSTMRMM | I5: CHSS-SU-CTS-A90-COS08 | J5: COMPRESOR CENTRIFUGO ELLIOTT 08 | K5: CTEC NOTI DOCU IMOP JBFI MACO MOVM PREC* | L5: TBTR | M5: 46160 | N5: 46160 | O5: TRAMI002 | P5: AAGUI058 | Q5: 45722 | R5: 45722 | S5: 46160 | T5: 46160 | U5: 46166 | X5: 89518.8 | Y5: 93988.3
A6: C82 | B6: PL | C6: 025 | D6: 29841887 | E6: 110329599 | F6: C82 | G6: STN REP. CAJA CONEX. ALUMB. PATIO S/E A | H6: CGSSERME | I6: CDEE-SEP-SEA-PAT | J6: PATIO 100KV | K6: CTEC NOTI DOCU IMOP JBFI KKMP PREC PROG | L6: TBTR | M6: 46160 | N6: 46160 | O6: SBAUT001 | P6: DVALD025 | Q6: 46093 | R6: 46092 | S6: 46160 | T6: 46160 | U6: 46160 | X6: 0.08 | Y6: 0.16
A7: C81 | B7: PL | C7: 010 | D7: 29972548 | E7: 110448901 | F7: C81 | G7: MRT 1S MEC LIMPIEZA MOLINO HARDINGE 1 | H7: CGSTMRMM | I7: CHSS-SU-PHC-MMH-MLH01 | J7: MOLINO HARDINGE Nº1 | K7: CTEC NOTI DOCU IMOP JBFI KKMP PREC PROG | L7: TRAT | M7: 46160 | N7: 46160 | O7: IP1020260420 | P7: CMEND008 | Q7: 46151 | R7: 46132 | S7: 46160 | T7: 46160 | U7: 46160 | V7: 139516 | W7: 251835 | X7: 89.11 | Y7: 89.11
A8: C81 | B8: PL | C8: 010 | D8: 29972555 | E8: 110448908 | F8: C81 | G8: MRT 1S MTTO CORREA 132 | H8: CGSTMRMM | I8: CHSS-SU-PHC-TCH-CT132 | J8: CORREA TRANSPORTADORA Nº132 | K8: CTEC NOTI DOCU IMOP JBFI KKMP PREC PROG | L8: TRAT | M8: 46160 | N8: 46160 | O8: IP1020260420 | P8: CMEND008 | Q8: 46151 | R8: 46132 | S8: 46160 | T8: 46160 | U8: 46160 | V8: 225688 | W8: 419098 | X8: 267.37 | Y8: 267.37
A9: C81 | B9: PL | C9: 010 | D9: 29972558 | E9: 110448911 | F9: C81 | G9: MRT 1S LIMPIEZA FILTRO DE MANGA | H9: CGSTMRMM | I9: CHSS-SU-PHC-SAL-SIL01 | J9: SILO 01 | K9: CTEC NOTI DOCU IMOP JBFI KKMP PREC PROG | L9: TRAT | M9: 46160 | N9: 46160 | O9: IP1020260420 | P9: CMEND008 | Q9: 46151 | R9: 46132 | S9: 46160 | T9: 46160 | U9: 46160 | V9: 225920 | W9: 419420 | X9: 0.06 | Y9: 0.06
A10: C81 | B10: PL | C10: 025 | D10: 30023764 | E10: 110499029 | F10: C81 | G10: (Q) COMP 20 -CAMBIO DE ENFRIADERA | H10: CGSTMRMM | I10: CHSS-SU-CTS-A30-CAP20 | J10: COMPRESOR CENTRIFUGO 20 | K10: LIB. NOTP DOCU IMOP KKMP PREC PROG | L10: TRAT | M10: 46160 | N10: 46164 | O10: VVERG011 | P10: AAGUI058 | Q10: 46151 | R10: 46147 | S10: 46160 | T10: 46160 | X10: 1.33 | Y10: 1.35
A11: C81 | B11: PL | C11: 025 | D11: 30023767 | E11: 110499035 | F11: C81 | G11: (Q) 48M MTTO COMPRESOR 08 | H11: CGSTMRMM | I11: CHSS-SU-CTS-A90-COS08 | J11: COMPRESOR CENTRIFUGO ELLIOTT 08 | K11: LIB. NOTP DOCU IMOP KKMP PREC PROG | L11: TRAT | M11: 46160 | N11: 46163 | O11: VVERG011 | P11: AAGUI058 | Q11: 46151 | R11: 46147 | S11: 46160 | T11: 46160 | X11: 7927.93 | Y11: 9263.71
A12: C81 | B12: PL | C12: 025 | D12: 30023741 | E12: 110499456 | F12: C81 | G12: Limpieza de Linea 1 de CAL | H12: CGSTMRMM | I12: CHSS-SU-PHC-TLC-SPIVV | J12: SISTEMA PIPING Y VALVULAS | K12: CTEC NOTI DOCU IMOP JBFI KKMP PREC PROG | L12: TRAT | M12: 46160 | N12: 46165 | O12: VVERG011 | P12: CMEND008 | Q12: 46151 | R12: 46147 | S12: 46160 | T12: 46160 | U12: 46162 | X12: 1.09 | Y12: 1.09
A13: C81 | B13: PL | C13: 010 | D13: 30027247 | E13: 110500509 | F13: C81 | G13: MRT 6M MTTO COMPRESOR N°29 | H13: CGSTMRMM | I13: CHSS-SU-CTS-A30-CAP29 | J13: COMPRESOR CENTRIFUGO 29 | K13: CTEC NOTI DOCU IMOP JBFI MACO MOVM PREC* | L13: TBTR | M13: 46160 | N13: 46162 | O13: VVERG011 | P13: AAGUI058 | Q13: 46148 | R13: 46148 | S13: 46160 | T13: 46159 | U13: 46164 | V13: 136288 | W13: 246318 | X13: 18156.57 | Y13: 19715.27
A14: C81 | B14: NP | C14: 035 | D14: 30029627 | E14: 110513924 | F14: C81 | G14: BAC 1 sin protección parte móvil | H14: CGSTMRMM | I14: CHSS-SU-CTS-GDV-CALD3-BC1 | J14: BOMBA BAC 1 Caldera N°3 | K14: CTEC NOTI DOCU IMOP JBFI KKMP PREC | L14: TBTR | M14: 46160 | N14: 46160 | O14: MJAIM002 | P14: CMEND008 | Q14: 46160 | R14: 46153 | S14: 46160 | T14: 46156 | U14: 46160 | X14: 89.1 | Y14: 89.1
A15: C81 | B15: NP | C15: 035 | D15: 30055856 | E15: 110531565 | F15: C81 | G15: CAMBIO filtro aire C27 ADM SATURADO | H15: CGSTMRMM | I15: CHSS-SU-CTS-A70-CAP27 | J15: COMPRESOR 27 | K15: CTEC NOTI DOCU IMOP JBFI KKMP PREC | L15: TBTR | M15: 46160 | N15: 46160 | O15: MJAIM002 | P15: CMEND008 | Q15: 46160 | R15: 46159 | S15: 46160 | T15: 46160 | U15: 46160 | X15: 89.1 | Y15: 89.1
A16: C81 | B16: PL | C16: 025 | D16: 28691634 | E16: 109207353 | F16: C81 | G16: COMP 8 Cambio rotor de alta (ACT) | H16: CGSTMRMM | I16: CHSS-SU-CTS-A90-COS08 | J16: COMPRESOR CENTRIFUGO ELLIOTT 08 | K16: CTEC NOTI DOCU IMOP JBFI MACO MOVM PREC* | L16: TBTR | M16: 46161 | N16: 46162 | O16: TRAMI002 | P16: AAGUI058 | Q16: 45734 | R16: 45734 | S16: 46161 | T16: 46161 | U16: 46166 | X16: 86149.71 | Y16: 86149.71
A17: C81 | B17: PL | C17: 025 | D17: 28691636 | E17: 109207578 | F17: C81 | G17: COMP 8 Cambio roto de baja (ACT) | H17: CGSTMRMM | I17: CHSS-SU-CTS-A90-COS08 | J17: COMPRESOR CENTRIFUGO ELLIOTT 08 | K17: CTEC NOTI DOCU IMOP JBFI MACO MOVM PREC* | L17: TBTR | M17: 46161 | N17: 46162 | O17: TRAMI002 | P17: AAGUI058 | Q17: 45734 | R17: 45734 | S17: 46161 | T17: 46161 | U17: 46166 | X17: 74171.22 | Y17: 74171.22
A18: C81 | B18: PL | C18: 025 | D18: 29498011 | E18: 110005386 | F18: C81 | G18: R-COMP 12 PORTA FILTRO AGUA DESGASTE | H18: CGSTMRMM | I18: CHSS-SU-CTS-A90-COS12-SEN-ENFA | J18: ENFRIADERA DE AGUA | K18: CTEC NOTI DOCU IMOP JBFI MACO MOVM PREC* | L18: TBTR | M18: 46161 | N18: 46161 | O18: VVERG011 | P18: AAGUI058 | Q18: 45993 | R18: 45986 | S18: 46161 | T18: 46162 | U18: 46162 | X18: 11985.98 | Y18: 11985.97
A19: C81 | B19: PL | C19: 010 | D19: 29972549 | E19: 110448902 | F19: C81 | G19: MRT 1S MEC LIMPIEZA MOLINO HARDINGE 2 | H19: CGSTMRMM | I19: CHSS-SU-PHC-MMH-MLH02 | J19: MOLINO HARDINGE Nº2 | K19: CTEC NOTI DOCU IMOP JBFI KKMP PREC PROG | L19: TRAT | M19: 46161 | N19: 46161 | O19: IP1020260420 | P19: CMEND008 | Q19: 46151 | R19: 46132 | S19: 46161 | T19: 46161 | U19: 46161 | V19: 139517 | W19: 251836 | X19: 89.11 | Y19: 89.11
A20: C81 | B20: PL | C20: 010 | D20: 29972556 | E20: 110448909 | F20: C81 | G20: MRT 1S MTTO CORREA 129 | H20: CGSTMRMM | I20: CHSS-SU-PHC-TCH-CT129 | J20: CORREA TRANSPORTADORA Nº129 | K20: CTEC NOTI DOCU IMOP JBFI KKMP PREC PROG | L20: TRAT | M20: 46161 | N20: 46161 | O20: IP1020260420 | P20: CMEND008 | Q20: 46151 | R20: 46132 | S20: 46161 | T20: 46161 | U20: 46161 | V20: 225688 | W20: 419099 | X20: 267.37 | Y20: 267.37
A21: C81 | B21: PL | C21: 010 | D21: 29993410 | E21: 110468786 | F21: C81 | G21: MRT 3S MEC MTTO ANÁLISIS VIBRACIONES CTR | H21: CGSTMRMM | I21: CHSS-SU-CTR-INS | J21: INSTALACIONES INDUSTRIALES | K21: CTEC NOTI DOCU IMOP JBFI KKMP PREC PROG | L21: TBTR | M21: 46161 | N21: 46161 | O21: IP1020260427 | P21: CMEND008 | Q21: 46151 | R21: 46139 | S21: 46161 | T21: 46162 | U21: 46162 | V21: 225372 | W21: 418430 | X21: 0.03 | Y21: 0.03
A22: C81 | B22: PL | C22: 010 | D22: 30026607 | E22: 110500458 | F22: C81 | G22: MRT 4S MEC INSP SOPLADOR N°7 | H22: CGSTMRMM | I22: CHSS-SU-CTS-A20-SOP07 | J22: SOPLADOR INGERSOL RAND Nº 7 | K22: CTEC NOTI DOCU IMOP JBFI KKMP PREC PROG | L22: TBTR | M22: 46161 | N22: 46161 | O22: IP1020260506 | P22: CMEND008 | Q22: 46151 | R22: 46148 | S22: 46161 | T22: 46163 | U22: 46163 | V22: 225357 | W22: 418515 | X22: 2155.39 | Y22: 2155.39
A23: C81 | B23: NP | C23: 035 | D23: 30049115 | E23: 110525041 | F23: C81 | G23: Filtració de agua por válvula | H23: CGSTMRMM | I23: CHSS-SU-CTS-GDV-BAC01-VAL-VALM | J23: VALVULA DE FLUJO MINIMO | K23: CTEC NOTI DOCU IMOP JBFI KKMP PREC | L23: TRAT | M23: 46161 | N23: 46161 | O23: MJAIM002 | P23: CMEND008 | Q23: 46161 | R23: 46156 | S23: 46161 | T23: 46161 | U23: 46161 | X23: 0.04 | Y23: 0.04
A24: C81 | B24: NP | C24: 035 | D24: 30049117 | E24: 110537056 | F24: C81 | G24: Cambio llave de corte tubo nivel | H24: CGSTMRMM | I24: CHSS-SU-CTS-A90-COS01-SEN-ENFA | J24: ENFRIADERA DE AGUA | K24: CTEC NOTI DOCU IMOP JBFI KKMP PREC | L24: TBTR | M24: 46161 | N24: 46161 | O24: MCHAV005 | P24: CMEND008 | Q24: 46161 | R24: 46160 | S24: 46161 | T24: 46161 | U24: 46161 | X24: 445.3 | Y24: 445.3
A25: C81 | B25: PL | C25: 025 | D25: 28846284 | E25: 109356986 | F25: C81 | G25: Cambio adaptadores en compresores 90 psi | H25: CGSTMRMM | I25: CHSS-SU-CTS-A90 | J25: GENERACION DE AIRE 90 PSIG | K25: CTEC NOTI DOCU IMOP JBFI MACO MOVM PREC* | L25: TBTR | M25: 46162 | N25: 46162 | O25: TRAMI002 | P25: AAGUI058 | Q25: 45789 | R25: 45782 | S25: 46162 | T25: 46162 | U25: 46166 | X25: 4758.25 | Y25: 6270.39
A26: C81 | B26: PL | C26: 025 | D26: 28850844 | E26: 109361620 | F26: C81 | G26: Mejoras líneas lubricación sopladores. | H26: CGSTMRMM | I26: CHSS-SU-CTS-A20 | J26: GENERACION DE AIRE DE 20 LB | K26: CTEC NOTI DOCU IMOP JBFI MACO MOVM PREC* | L26: TBTR | M26: 46162 | N26: 46162 | O26: TRAMI002 | P26: AAGUI058 | Q26: 45789 | R26: 45783 | S26: 46162 | T26: 46162 | U26: 46166 | X26: 1282.42 | Y26: 1815.17
A27: C82 | B27: PL | C27: 025 | D27: 29948766 | E27: 110440236 | F27: C82 | G27: STN CAMBIO EXTINTOR UPS N°2 SCADA S/E A | H27: CGSSERME | I27: CHSS-SE-SUP-SPA-SUBEA-BAT-UP2 | J27: UPS N°2 CONTROL SCADA SUB-A | K27: CTEC NOTI DOCU IMOP JBFI KKMP PREC PROG | L27: TBTR | M27: 46162 | N27: 46162 | O27: SBAUT001 | P27: ASALA015 | Q27: 46137 | R27: 46128 | S27: 46162 | T27: 46162 | U27: 46162 | X27: 0.02 | Y27: 0.02
A28: C82 | B28: PL | C28: 025 | D28: 29948764 | E28: 110440238 | F28: C82 | G28: STN CAMBIO EXTINTOR UPS N°1 SCADA S/E A | H28: CGSSERME | I28: CHSS-SE-SUP-SPA-SUBEA-BAT-UP1 | J28: UPS N°1 CONTROL SCADA SUB-A | K28: CTEC NOTI DOCU IMOP JBFI KKMP PREC PROG | L28: TBTR | M28: 46162 | N28: 46162 | O28: SBAUT001 | P28: ASALA015 | Q28: 46137 | R28: 46128 | S28: 46162 | T28: 46162 | U28: 46162 | X28: 0.02 | Y28: 0.02
A29: C81 | B29: PL | C29: 010 | D29: 29971638 | E29: 110448004 | F29: C81 | G29: MRT 4S MEC MTTO PUENTE GRUA SOPLADORES | H29: CGSTMRMM | I29: CHSS-SU-CTS-AUX-PGR20 | J29: PUENTE GRÚA 20 TONS NAVE SOPLADORES | K29: LIB. NOTI IMOP JBFI KKMP PREC PROG | L29: TBTR | M29: 46162 | N29: 46162 | O29: IP1020260420 | P29: VVERG011 | Q29: 46147 | R29: 46132 | S29: 46162 | T29: 46165 | U29: 46165 | V29: 225701 | W29: 419112 | X29: 0.18 | Y29: 0.18
A30: C81 | B30: PL | C30: 010 | D30: 29972550 | E30: 110448903 | F30: C81 | G30: MRT 1S MEC LIMPIEZA MOLINO TORRE | H30: CGSTMRMM | I30: CHSS-SU-PHC-MMV-MLNTR | J30: MOLINO TORRE | K30: CTEC NOTI DOCU IMOP JBFI KKMP PREC PROG | L30: TRAT | M30: 46162 | N30: 46162 | O30: IP1020260420 | P30: CMEND008 | Q30: 46151 | R30: 46132 | S30: 46162 | T30: 46161 | U30: 46162 | V30: 139518 | W30: 251837 | X30: 89.2 | Y30: 89.2
A31: C81 | B31: PL | C31: 010 | D31: 29993411 | E31: 110468787 | F31: C81 | G31: MRT 3S MEC MTTO ANÁLISIS VIBRACIONES PHC | H31: CGSTMRMM | I31: CHSS-SU-PHC-INS | J31: INSTALACIONES INDUSTRIALES PLANTA CAL | K31: CTEC NOTI DOCU IMOP JBFI KKMP PREC PROG | L31: TBTR | M31: 46162 | N31: 46162 | O31: IP1020260427 | P31: CMEND008 | Q31: 46151 | R31: 46139 | S31: 46162 | T31: 46161 | U31: 46161 | V31: 225372 | W31: 418431 | X31: 0.03 | Y31: 0.03
A32: C82 | B32: PL | C32: 025 | D32: 30031043 | E32: 110504750 | F32: C82 | G32: STN INSP PEDESTRE LINEA ENC TCHITACK | H32: CGSSERME | I32: CDEE-SEP-SP2 | J32: SUBESTACION Tchitack | K32: LIB. NOTP IMOP KKMP PREC PROG | L32: TRAT | M32: 46162 | N32: 46173 | O32: SBAUT001 | P32: JCARR068 | Q32: 46149 | R32: 46149 | S32: 46162 | T32: 46162 | X32: 0.32 | Y32: 0.96
A33: C81 | B33: NP | C33: 035 | D33: 30069082 | E33: 110543322 | F33: C81 | G33: Revision C2: V/v venteo trabada | H33: CGSTMRMM | I33: CHSS-SU-CTS-A90-COS02-INS | J33: SISTEMA DE CONTROL Y AUTOMATIZACION | K33: CTEC NOTI DOCU IMOP JBFI KKMP PREC | L33: TBTR | M33: 46162 | N33: 46162 | O33: MREINES | P33: CMEND008 | Q33: 46161 | R33: 46161 | S33: 46162 | T33: 46161 | U33: 46161 | X33: 178.12 | Y33: 178.12
A34: C81 | B34: PL | C34: 025 | D34: 29532244 | E34: 110023389 | F34: C81 | G34: COMP 28 PORTA FILTRO AGUA DESGASTE | H34: CGSTMRMM | I34: CHSS-SU-CTS-A30-CAP28-SEN | J34: SISTEMA DE ENFRIAMIENTO | K34: CTEC NOTI DOCU IMOP JBFI MACO MOVM PREC* | L34: TBTR | M34: 46163 | N34: 46163 | O34: VVERG011 | P34: AAGUI058 | Q34: 45993 | R34: 45992 | S34: 46163 | T34: 46163 | U34: 46166 | X34: 11985.97 | Y34: 11985.97
A35: C81 | B35: PL | C35: 025 | D35: 29532245 | E35: 110023390 | F35: C81 | G35: COMP 29 PORTA FILTRO AGUA DESGASTE | H35: CGSTMRMM | I35: CHSS-SU-CTS-A30-CAP29-SEN | J35: SISTEMA DE ENFRIAMIENTO | K35: CTEC NOTI DOCU IMOP JBFI MACO MOVM PREC* | L35: TBTR | M35: 46163 | N35: 46163 | O35: VVERG011 | P35: AAGUI058 | Q35: 45993 | R35: 45992 | S35: 46163 | T35: 46163 | U35: 46166 | X35: 11985.97 | Y35: 11985.97
A36: C82 | B36: PL | C36: 010 | D36: 29775660 | E36: 110258373 | F36: C82 | G36: MTTO. PAÑO TRANSFORMADOR 9 S/E 10A | H36: CGSSERME | I36: CHSS-SE-PAT-S1A-PANT9 | J36: PAÑO TRANSFORMADOR Nº9 | K36: CTEC NOTI DOCU IMOP JBFI KKMP PREC PROG | L36: TBTR | M36: 46163 | N36: 46163 | O36: IP1020260216 | P36: JCARR068 | Q36: 46155 | R36: 46069 | S36: 46163 | T36: 46163 | U36: 46165 | V36: 79880 | W36: 143912 | X36: 1030 | Y36: 1030
A37: C81 | B37: PL | C37: 010 | D37: 29971634 | E37: 110448000 | F37: C81 | G37: MRT 4S MTTO MEC BOMBA AURORA | H37: CGSTMRMM | I37: CHSS-SU-PHC-MMH-BBAPZ | J37: BOMBA POZO AURORA 15 | K37: CTEC NOTI DOCU IMOP JBFI KKMP PREC PROG | L37: TBTR | M37: 46163 | N37: 46163 | O37: IP1020260420 | P37: CMEND008 | Q37: 46151 | R37: 46132 | S37: 46163 | T37: 46162 | U37: 46162 | V37: 225401 | W37: 418491 | X37: 89.12 | Y37: 89.12
A38: C81 | B38: PL | C38: 010 | D38: 29971635 | E38: 110448001 | F38: C81 | G38: MRT 4S MTTO MEC BOMBA 3C | H38: CGSTMRMM | I38: CHSS-SU-PHC-TLC-BBA3C | J38: BOMBA 3C CCON | K38: CTEC NOTI DOCU IMOP JBFI KKMP PREC PROG | L38: TRAT | M38: 46163 | N38: 46163 | O38: IP1020260420 | P38: CMEND008 | Q38: 46151 | R38: 46132 | S38: 46163 | T38: 46161 | U38: 46161 | V38: 225432 | W38: 418492 | X38: 89.12 | Y38: 89.12
A39: C82 | B39: PL | C39: 020 | D39: 30020981 | E39: 110495171 | F39: C82 | G39: INSPECCIÓN SAPCI S/E K1 SALA CONTROL | H39: CGSSERME | I39: CHSS-SE-SUP-SPA-SUBK1-SAP | J39: SISTEMA SAPCI S/E K1 | K39: CTEC NOTI DOCU IMOP JBFI KKMP PREC PROG | L39: TBTR | M39: 46163 | N39: 46163 | O39: IP1020260505 | P39: ASALA015 | Q39: 46155 | R39: 46147 | S39: 46163 | T39: 46163 | U39: 46163 | V39: 225930 | W39: 419472 | X39: 0.03 | Y39: 0.03
A40: C82 | B40: PL | C40: 025 | D40: 29823944 | E40: 110325637 | F40: C82 | G40: PRO - Lvtmto Printouts Tchitack 220kV | H40: CGSSERME | I40: CHSS-SE-SUP-SPA-SUBTC-SWG-SWG1 | J40: SWITCHGEAR GIS 220KV 2000A 25KA | K40: CTEC NOTI DOCU IMOP JBFI KKMP PREC PROG | L40: TBTR | M40: 46164 | N40: 46164 | O40: AVALE004 | P40: JGALA017 | Q40: 46091 | R40: 46091 | S40: 46164 | T40: 46164 | U40: 46164 | X40: 494.4 | Y40: 329.6
...

Sheet Tabla
A1: Avisos Pendientes
A2: Proceso | B2: Gr.Planif | C2: Gr.planif.PM | D2: Avisos
A3: 02 SUMINISTRO ELECTRICO DCH | B3: C82 | C3: Pl.Dist.Energ.Elec | D3: 3
A4: Total general | D4: 3
A11: Órdenes Pendientes
A12: Proceso | B12: Gr. Planif | C12: Gr.planif.PM | D12: Órdenes
A13: 03 PLANTAS DE SUMINISTROS DCH | B13: C81 | C13: Pl.Termoelec.Chuq. | D13: 10
A14: 99 ESENCIALES INFRA. SERV. DCH | B14: C71 | C14: Pl.Maestranza.Cent | D14: 3
B15: C82 | C15: Pl.Dist.Energ.Elec | D15: 4
A16: 01 INFRAESTRUC CONC DCH | B16: C71 | C16: Pl.Maestranza.Cent | D16: 8
B17: C84 | C17: Pl.Tall.Electr.Cen | D17: 14
B18: C72 | C18: Pl.Calderería.Cent | D18: 3
A19: 02 SUMINISTRO ELECTRICO DCH | B19: C82 | C19: Pl.Dist.Energ.Elec | D19: 12
A20: Total general | D20: 54
A27: % Trabajo Planificado
A28: Suma de HH Totales Reales | D28: Criterio
A29: Proceso | B29: Gr. planif | C29: Gr. planif.PM | D29: Planificado | E29: Imprevisto | F29: Total general | G29: Cumplimiento
A30: 02 SUMINISTRO ELECTRICO DCH | B30: C82 | C30: Pl.Dist.Energ.Elec | D30: 179 | F30: 179 | G30: =D30/F30 -> 1
A31: 03 PLANTAS DE SUMINISTROS DCH | B31: C81 | C31: Pl.Termoelec.Chuq. | D31: 864.6 | E31: 35.9 | F31: 900.5 | G31: =D31/F31 -> 0.96013326
A32: 99 ESENCIALES INFRA. SERV. DCH | B32: C82 | C32: Pl.Dist.Energ.Elec | D32: 13 | F32: 13 | G32: =D32/F32 -> 1
B33: C81 | C33: Pl.Termoelec.Chuq. | D33: 16.5 | F33: 16.5 | G33: =D33/F33 -> 1
A34: Total general | D34: 1073.1 | E34: 35.9 | F34: 1109 | G34: =D34/F34 -> 0.96762849
A42: Programa Semanal
A43: Suma de Total Op. Programadas | D43: Criterio
A44: Proceso | B44: Gr.planif | C44: Gr.planif.PM | D44: Cumple | E44: No Cumple | F44: Total general | G44: % Cumplimiento
A45: 02 SUMINISTRO ELECTRICO DCH | B45: C82 | C45: Pl.Dist.Energ.Elec | D45: 33 | E45: 4 | F45: 37 | G45: 0.9048
A46: 03 PLANTAS DE SUMINISTROS DCH | B46: C81 | C46: Pl.Termoelec.Chuq. | D46: 232 | E46: 20 | F46: 252 | G46: 0.9405
A47: 99 ESENCIALES INFRA. SERV. DCH | B47: C82 | C47: Pl.Dist.Energ.Elec | D47: 5 | F47: 5 | G47: =D47/F47 -> 1
B48: C81 | C48: Pl.Termoelec.Chuq. | D48: 9 | F48: 9 | G48: =D48/F48 -> 1
A49: Total general | D49: 279 | E49: 24 | F49: 303 | G49: 0.9373
A56: Plan Matriz
A57: Suma de Cantidad de Operaciones totales | D57: Criterio
A58: Proceso | B58: Gr.planif | C58: Gr.planif.PM | D58: Cumple | E58: No Cumple | F58: Total general | G58: % Cumplimiento
A59: 02 SUMINISTRO ELECTRICO DCH | B59: C82 | C59: Pl.Dist.Energ.Elec | D59: 11 | E59: 4 | F59: 15 | G59: =D59/F59 -> 0.73333333
A60: 03 PLANTAS DE SUMINISTROS DCH | B60: C81 | C60: Pl.Termoelec.Chuq. | D60: 134 | F60: 134 | G60: =D60/F60 -> 1
A61: 99 ESENCIALES INFRA. SERV. DCH | B61: C82 | C61: Pl.Dist.Energ.Elec | D61: 3 | F61: 3 | G61: =D61/F61 -> 1
B62: C81 | C62: Pl.Termoelec.Chuq. | D62: 18 | E62: 9 | F62: 27 | G62: =D62/F62 -> 0.66666667
B63: C71 | C63: Pl.Maestranza.Cent | E63: 9 | F63: 9 | G63: =D63/F63 -> 0
A64: Total general | D64: 166 | E64: 22 | F64: 188 | G64: =D64/F64 -> 0.88297872

Sheet Avisos Pendientes
A1: Año natural/Semana | B1: Fase | C1: Proceso | D1: SubProceso | E1: Aviso | F1: Txt. Breve | G1: Clase de aviso | H1: Prioridad | I1: Status de Sistema | J1: Fecha Aviso PM | K1: Gr.planif.PM | L1: Gr.Planif | M1: Orden mantenimiento | N1: Columna3 | O1: Puesto de trabajo | P1: Pto. Trabajo | Q1: Número de avisos pendientes
A2: 19.2026 | B2: 08 INFR SERVIC Y SUMIN DCH | C2: 02 SUMINISTRO ELECTRICO DCH | D2: CHSS-SE | E2: 30035659 | F2: Revision de Baterias Grupo Gen Tchitack | G2: M1 | H2: 3 | I2: DOCU MEAB | J2: 46151 | K2: Pl.Dist.Energ.Elec | L2: C82 | M2: # | N2: Sin asignar | O2: MANT. INT SUMINISTRO ELECTRICO | P2: CGSMPE03 | Q2: 1
A3: 19.2026 | B3: 08 INFR SERVIC Y SUMIN DCH | C3: 02 SUMINISTRO ELECTRICO DCH | D3: CHSS-SE | E3: 30035777 | F3: Mtto G. Generador Tchitack | G3: M1 | H3: 3 | I3: DOCU MEAB | J3: 46151 | K3: Pl.Dist.Energ.Elec | L3: C82 | M3: # | N3: Sin asignar | O3: MANT. INT SUMINISTRO ELECTRICO | P3: CGSMPE03 | Q3: 1
A4: 19.2026 | B4: 08 INFR SERVIC Y SUMIN DCH | C4: 02 SUMINISTRO ELECTRICO DCH | D4: CHSS-SE | E4: 30037668 | F4: EJE. BAJO NIVEL CONSERVADOR CDBC ATR 2 | G4: M1 | H4: 3 | I4: DOCU MEAB | J4: 46152 | K4: Pl.Dist.Energ.Elec | L4: C82 | M4: # | N4: Sin asignar | O4: MANT & PLANIF SUMINISTRO ELECTRICO | P4: CGSSERME | Q4: 1
A5: Resultado total | Q5: 3

Sheet Órdenes Pendientes
A1: Gr.planif.PM | B1: Gr. Planif | C1: Fase | D1: Proceso | E1: Sub-Proceso | F1: Orden mantenimiento | G1: Txt. Breve | H1: Status de Sistema | I1: Clase de orden | J1: Clase actividad PM | K1: Actividad PM | L1: Año natural/Semana | M1: Pto. Trabajo | N1: Puesto de trabajo | O1: Número de OT Pendientes
A2: Pl.Termoelec.Chuq. | B2: C81 | C2: 08 INFR SERVIC Y SUMIN DCH | D2: 03 PLANTAS DE SUMINISTROS DCH | E2: CHSS-SU | F2: 109423166 | G2: Alimentación cal desde silo 3/correa 129 | H2: LIB. IMOP MACO MOVM PREC TRAT | I2: PL | J2: Correctivo Planificado | K2: 025 | L2: 18.2026 | M2: MANT & PLANIF CENTRAL TERMICA SULFUROS | N2: CGSTMRMM | O2: 1
A3: Pl.Termoelec.Chuq. | B3: C81 | C3: 08 INFR SERVIC Y SUMIN DCH | D3: 03 PLANTAS DE SUMINISTROS DCH | E3: CHSS-SU | F3: 109501785 | G3: CAMBIO BBA 1B - FILTRACION SELLOS | H3: LIB. NOTP DOCU IMOP MACO PREC PROG TRAT | I3: PL | J3: Correctivo Planificado | K3: 025 | L3: 16.2026 | M3: MANT & PLANIF CENTRAL TERMICA SULFUROS | N3: CGSTMRMM | O3: 1
A4: Pl.Termoelec.Chuq. | B4: C81 | C4: 08 INFR SERVIC Y SUMIN DCH | D4: 03 PLANTAS DE SUMINISTROS DCH | E4: CHSS-SU | F4: 109613092 | G4: Cambio controlador y válvula de admisión | H4: LIB. IMOP MACO MOVM PREC TRAT | I4: PL | J4: Correctivo Planificado | K4: 025 | L4: 18.2026 | M4: MANT & PLANIF CENTRAL TERMICA SULFUROS | N4: CGSTMRMM | O4: 1
A5: Pl.Termoelec.Chuq. | B5: C81 | C5: 08 INFR SERVIC Y SUMIN DCH | D5: 03 PLANTAS DE SUMINISTROS DCH | E5: CHSS-SU | F5: 109613336 | G5: Cambio controlador y válvula de admisión | H5: LIB. IMOP MACO MOVM PREC TRAT | I5: PL | J5: Correctivo Planificado | K5: 025 | L5: 18.2026 | M5: MANT & PLANIF CENTRAL TERMICA SULFUROS | N5: CGSTMRMM | O5: 1
A6: Pl.Termoelec.Chuq. | B6: C81 | C6: 08 INFR SERVIC Y SUMIN DCH | D6: 03 PLANTAS DE SUMINISTROS DCH | E6: CHSS-SU | F6: 109613341 | G6: COMP22 Cbio controlador MK5 válvula admi | H6: LIB. IMOP MACO MOVM PREC TRAT | I6: PL | J6: Correctivo Planificado | K6: 025 | L6: 18.2026 | M6: MANT & PLANIF CENTRAL TERMICA SULFUROS | N6: CGSTMRMM | O6: 1
A7: Pl.Termoelec.Chuq. | B7: C81 | C7: 08 INFR SERVIC Y SUMIN DCH | D7: 03 PLANTAS DE SUMINISTROS DCH | E7: CHSS-SU | F7: 109654371 | G7: FUCO26 Cambio Tubo nivel Des Caldera 3 | H7: LIB. NOTI DOCU IMOP JBFI MACO MOVM PREC* | I7: PL | J7: Correctivo Planificado | K7: 025 | L7: 17.2026 | M7: MANT & PLANIF CENTRAL TERMICA SULFUROS | N7: CGSTMRMM | O7: 1
A8: Pl.Termoelec.Chuq. | B8: C81 | C8: 08 INFR SERVIC Y SUMIN DCH | D8: 03 PLANTAS DE SUMINISTROS DCH | E8: CHSS-SU | F8: 109882735 | G8: FLOTADOR EN MAL ESTADO SOPLADOR 8 | H8: ABIE IMOP KKMP PREC ENET | I8: PL | J8: Correctivo Planificado | K8: 025 | L8: 09.2026 | M8: MANT & PLANIF CENTRAL TERMICA SULFUROS | N8: CGSTMRMM | O8: 1
A9: Pl.Termoelec.Chuq. | B9: C81 | C9: 08 INFR SERVIC Y SUMIN DCH | D9: 03 PLANTAS DE SUMINISTROS DCH | E9: CHSS-SU | F9: 110005388 | G9: R-COMP 16 PORTA FILTRO AGUA DESGASTE | H9: LIB. IMOP MACO MOVM PREC TRAT | I9: PL | J9: Correctivo Planificado | K9: 025 | L9: 19.2026 | M9: MANT & PLANIF CENTRAL TERMICA SULFUROS | N9: CGSTMRMM | O9: 1
A10: Pl.Termoelec.Chuq. | B10: C81 | C10: 08 INFR SERVIC Y SUMIN DCH | D10: 03 PLANTAS DE SUMINISTROS DCH | E10: CHSS-SU | F10: 110011685 | G10: CTR FILTROS DE CARTUCHOS SATURADOS-MALOS | H10: LIB. IMOP MACO MOVM PREC PROG TRAT | I10: PL | J10: Correctivo Planificado | K10: 025 | L10: 11.2026 | M10: MANT & PLANIF CENTRAL TERMICA SULFUROS | N10: CGSTMRMM | O10: 1
A11: Pl.Termoelec.Chuq. | B11: C81 | C11: 08 INFR SERVIC Y SUMIN DCH | D11: 03 PLANTAS DE SUMINISTROS DCH | E11: CHSS-SU | F11: 110265635 | G11: R-Cambio caseta portafiltros comp 25 | H11: LIB. FMAT IMOP PREC TRAT | I11: PL | J11: Correctivo Planificado | K11: 025 | L11: 19.2026 | M11: MANT & PLANIF CENTRAL TERMICA SULFUROS | N11: CGSTMRMM | O11: 1
A12: Pl.Tall.Electr.Cen | B12: C84 | C12: 08 INFR SERVIC Y SUMIN DCH | D12: 01 INFRAESTRUC CONC DCH | E12: # | F12: 109565393 | G12: reparación Motor CT3 F3 22-319 TEC | H12: LIB. FMAT IMOP MOVM PREC TRAT | I12: ST | J12: Reparación | K12: 060 | L12: 19.2026 | M12: MANT & PLANIF. TALLER ELECTRICO CENTRAL | N12: CGSSERTE | O12: 1
A13: Pl.Tall.Electr.Cen | B13: C84 | C13: 08 INFR SERVIC Y SUMIN DCH | D13: 01 INFRAESTRUC CONC DCH | E13: # | F13: 109797748 | G13: MOTOR 355HP2300V105,4AMP1490RPM TEC S/T | H13: ABIE FENA IMOP KKMP PREC ENET | I13: ST | J13: Reparación | K13: 060 | L13: 18.2026 | M13: MANT & PLANIF. TALLER ELECTRICO CENTRAL | N13: CGSSERTE | O13: 1
... A55: Pl.Calderería.Cent | B55: C72 | C55: 08 INFR SERVIC Y SUMIN DCH | D55: 01 INFRAESTRUC CONC DCH | E55: # | F55: 110387265 | G55: CAMBIO CORAZA POSTE SH N°10104410 | H55: LIB. NOTP IMOP KKMP PREC PROG TRAT | I55: ST | J55: Reparación | K55: 060 | L55: 17.2026 | M55: SERVICIO INTERNO CALDERERIA | N55: CGSSTM03 | O55: 1
A56: Resultado total | O56: 54

Sheet % Trabajo Planificado
A1: Año natural/Semana | B1: Fase | C1: Proceso | D1: SubProceso | E1: Puesto de trabajo | F1: Psto. Trabaj | G1: Clase actividad PM | H1: Actividad PM | I1: Gr. planif | J1: Gr. planif.PM | K1: Orden mantenimiento | L1: Txt. Breve | M1: Status de Sistema | N1: Clase de orden | O1: Horizonte | P1: Fecha Libera Orden | Q1: Fecha inicio real | R1: Grupo hojas de ruta | S1: % Planificado (HH) | T1: HH Plan. Reales | U1: HH Totales Reales | V1: Criterio
A2: 21.2026 | B2: 08 INFR SERVIC Y SUMIN DCH | C2: 02 SUMINISTRO ELECTRICO DCH | D2: CDEE | E2: MANT & PLANIF SUMINISTRO ELECTRICO | F2: CGSSERME | G2: 025 | H2: Correctivo Planificado | I2: =VLOOKUP(Tbl_PctTrabajoPlanificado[[#This Row],[Orden mantenimiento]],Data!$E$2:$H$63,2,FALSE) -> C82 | J2: {=_xlfn.IFS(I2="C81","Pl.Termoelec.Chuq.",I2="C82","Pl.Dist.Energ.Elec",I2="C89","Pl.Mant.Ind.Electr",I2="CO0","Concentradora A0",I2="CO1","Concentradora A1",I2="CO2","Concentradora A2",I2="CB1","SAE Centralizado",I2="C71","Pl.Maestranza.Cent",I2="C72","Pl.Calderería.Cent",I2="C74","CONTRATOS METALMEC",I2="C40","Planif. Refinería",I2="SAPCI","SAPCI",TRUE,"Código no encontrado")} -> Pl.Dist.Energ.Elec | K2: 110329599 | L2: STN REP. CAJA CONEX. ALUMB. PATIO S/E A | M2: NOTI CTEC JBFI NLIQ PWF RESA PLAN | N2: PL | O2: =Tbl_PctTrabajoPlanificado[[#This Row],[Fecha inicio real]]-Tbl_PctTrabajoPlanificado[[#This Row],[Fecha Libera Orden]] -> 67 | P2: 46093 | Q2: 46160 | R2: 98949 | S2: 100 | T2: 8 | U2: 8 | V2: Planificado
A3: 21.2026 | B3: 08 INFR SERVIC Y SUMIN DCH | C3: 02 SUMINISTRO ELECTRICO DCH | D3: CDEE | E3: MANT & PLANIF SUMINISTRO ELECTRICO | F3: CGSSERME | G3: 025 | H3: Correctivo Planificado | I3: =VLOOKUP(Tbl_PctTrabajoPlanificado[[#This Row],[Orden mantenimiento]],Data!$E$2:$H$63,2,FALSE) -> C82 | J3: {=_xlfn.IFS(I3="C81","Pl.Termoelec.Chuq.",I3="C82","Pl.Dist.Energ.Elec",I3="C89","Pl.Mant.Ind.Electr",I3="CO0","Concentradora A0",I3="CO1","Concentradora A1",I3="CO2","Concentradora A2",I3="CB1","SAE Centralizado",I3="C71","Pl.Maestranza.Cent",I3="C72","Pl.Calderería.Cent",I3="C74","CONTRATOS METALMEC",I3="C40","Planif. Refinería",I3="SAPCI","SAPCI",TRUE,"Código no encontrado")} -> Pl.Dist.Energ.Elec | K3: 110504750 | L3: STN INSP PEDESTRE LINEA ENC TCHITACK | M3: NOTI JBFI LIB. NLIQ PLAN PWF | N3: PL | O3: =Tbl_PctTrabajoPlanificado[[#This Row],[Fecha inicio real]]-Tbl_PctTrabajoPlanificado[[#This Row],[Fecha Libera Orden]] -> 13 | P3: 46149 | Q3: 46162 | R3: 98949 | S3: 100 | T3: 32 | U3: 32 | V3: Planificado
A4: 21.2026 | B4: 08 INFR SERVIC Y SUMIN DCH | C4: 02 SUMINISTRO ELECTRICO DCH | D4: CHSS-SE | E4: MANT & PLANIF SUMINISTRO ELECTRICO | F4: CGSSERME | G4: 010 | H4: Preventivo Sistemático | I4: =VLOOKUP(Tbl_PctTrabajoPlanificado[[#This Row],[Orden mantenimiento]],Data!$E$2:$H$63,2,FALSE) -> C82 | J4: {=_xlfn.IFS(I4="C81","Pl.Termoelec.Chuq.",I4="C82","Pl.Dist.Energ.Elec",I4="C89","Pl.Mant.Ind.Electr",I4="CO0","Concentradora A0",I4="CO1","Concentradora A1",I4="CO2","Concentradora A2",I4="CB1","SAE Centralizado",I4="C71","Pl.Maestranza.Cent",I4="C72","Pl.Calderería.Cent",I4="C74","CONTRATOS METALMEC",I4="C40","Planif. Refinería",I4="SAPCI","SAPCI",TRUE,"Código no encontrado")} -> Pl.Dist.Energ.Elec | K4: 110258373 | L4: MTTO. PAÑO TRANSFORMADOR 9 S/E 10A | M4: NOTI CTEC JBFI NLIQ PWF RESA PLAN | N4: PL | O4: =Tbl_PctTrabajoPlanificado[[#This Row],[Fecha inicio real]]-Tbl_PctTrabajoPlanificado[[#This Row],[Fecha Libera Orden]] -> 8 | P4: 46155 | Q4: 46163 | R4: 24496 | S4: 100 | T4: 1 | U4: 1 | V4: Planificado
A5: 21.2026 | B5: 08 INFR SERVIC Y SUMIN DCH | C5: 02 SUMINISTRO ELECTRICO DCH | D5: CHSS-SE | E5: MANT & PLANIF SUMINISTRO ELECTRICO | F5: CGSSERME | G5: 010 | H5: Preventivo Sistemático | I5: =VLOOKUP(Tbl_PctTrabajoPlanificado[[#This Row],[Orden mantenimiento]],Data!$E$2:$H$63,2,FALSE) -> C82 | J5: {=_xlfn.IFS(I5="C81","Pl.Termoelec.Chuq.",I5="C82","Pl.Dist.Energ.Elec",I5="C89","Pl.Mant.Ind.Electr",I5="CO0","Concentradora A0",I5="CO1","Concentradora A1",I5="CO2","Concentradora A2",I5="CB1","SAE Centralizado",I5="C71","Pl.Maestranza.Cent",I5="C72","Pl.Calderería.Cent",I5="C74","CONTRATOS METALMEC",I5="C40","Planif. Refinería",I5="SAPCI","SAPCI",TRUE,"Código no encontrado")} -> Pl.Dist.Energ.Elec | K5: 110258373 | L5: MTTO. PAÑO TRANSFORMADOR 9 S/E 10A | M5: NOTI CTEC JBFI NLIQ PWF PLAN | N5: PL | O5: =Tbl_PctTrabajoPlanificado[[#This Row],[Fecha inicio real]]-Tbl_PctTrabajoPlanificado[[#This Row],[Fecha Libera Orden]] -> 8 | P5: 46155 | Q5: 46163 | R5: 24496 | S5: 100 | T5: 24 | U5: 24 | V5: Planificado
A6: 21.2026 | B6: 08 INFR SERVIC Y SUMIN DCH | C6: 02 SUMINISTRO ELECTRICO DCH | D6: CHSS-SE | E6: MANT & PLANIF SUMINISTRO ELECTRICO | F6: CGSSERME | G6: 010 | H6: Preventivo Sistemático | I6: =VLOOKUP(Tbl_PctTrabajoPlanificado[[#This Row],[Orden mantenimiento]],Data!$E$2:$H$63,2,FALSE) -> C82 | J6: {=_xlfn.IFS(I6="C81","Pl.Termoelec.Chuq.",I6="C82","Pl.Dist.Energ.Elec",I6="C89","Pl.Mant.Ind.Electr",I6="CO0","Concentradora A0",I6="CO1","Concentradora A1",I6="CO2","Concentradora A2",I6="CB1","SAE Centralizado",I6="C71","Pl.Maestranza.Cent",I6="C72","Pl.Calderería.Cent",I6="C74","CONTRATOS METALMEC",I6="C40","Planif. Refinería",I6="SAPCI","SAPCI",TRUE,"Código no encontrado")} -> Pl.Dist.Energ.Elec | K6: 110464146 | L6: Termografía 2M S/E A | M6: NOTI CTEC JBFI NLIQ PWF PLAN | N6: PL | O6: =Tbl_PctTrabajoPlanificado[[#This Row],[Fecha inicio real]]-Tbl_PctTrabajoPlanificado[[#This Row],[Fecha Libera Orden]] -> 11 | P6: 46155 | Q6: 46166 | R6: 25012 | S6: 100 | T6: 6 | U6: 6 | V6: Planificado
A7: 21.2026 | B7: 08 INFR SERVIC Y SUMIN DCH | C7: 02 SUMINISTRO ELECTRICO DCH | D7: CHSS-SE | E7: MANT & PLANIF SUMINISTRO ELECTRICO | F7: CGSSERME | G7: 010 | H7: Preventivo Sistemático | I7: =VLOOKUP(Tbl_PctTrabajoPlanificado[[#This Row],[Orden mantenimiento]],Data!$E$2:$H$63,2,FALSE) -> C82 | J7: {=_xlfn.IFS(I7="C81","Pl.Termoelec.Chuq.",I7="C82","Pl.Dist.Energ.Elec",I7="C89","Pl.Mant.Ind.Electr",I7="CO0","Concentradora A0",I7="CO1","Concentradora A1",I7="CO2","Concentradora A2",I7="CB1","SAE Centralizado",I7="C71","Pl.Maestranza.Cent",I7="C72","Pl.Calderería.Cent",I7="C74","CONTRATOS METALMEC",I7="C40","Planif. Refinería",I7="SAPCI","SAPCI",TRUE,"Código no encontrado")} -> Pl.Dist.Energ.Elec | K7: 110464147 | L7: Termografía 2M S/E Chuquicamata | M7: NOTI CTEC JBFI NLIQ PWF PLAN | N7: PL | O7: =Tbl_PctTrabajoPlanificado[[#This Row],[Fecha inicio real]]-Tbl_PctTrabajoPlanificado[[#This Row],[Fecha Libera Orden]] -> 11 | P7: 46155 | Q7: 46166 | R7: 25012 | S7: 100 | T7: 6 | U7: 6 | V7: Planificado
A8: 21.2026 | B8: 08 INFR SERVIC Y SUMIN DCH | C8: 02 SUMINISTRO ELECTRICO DCH | D8: CHSS-SE | E8: MANT & PLANIF SUMINISTRO ELECTRICO | F8: CGSSERME | G8: 010 | H8: Preventivo Sistemático | I8: =VLOOKUP(Tbl_PctTrabajoPlanificado[[#This Row],[Orden mantenimiento]],Data!$E$2:$H$63,2,FALSE) -> C82 | J8: {=_xlfn.IFS(I8="C81","Pl.Termoelec.Chuq.",I8="C82","Pl.Dist.Energ.Elec",I8="C89","Pl.Mant.Ind.Electr",I8="CO0","Concentradora A0",I8="CO1","Concentradora A1",I8="CO2","Concentradora A2",I8="CB1","SAE Centralizado",I8="C71","Pl.Maestranza.Cent",I8="C72","Pl.Calderería.Cent",I8="C74","CONTRATOS METALMEC",I8="C40","Planif. Refinería",I8="SAPCI","SAPCI",TRUE,"Código no encontrado")} -> Pl.Dist.Energ.Elec | K8: 110472936 | L8: Termografía 2M S/E 10A | M8: NOTI CTEC JBFI NLIQ PWF PLAN | N8: PL | O8: =Tbl_PctTrabajoPlanificado[[#This Row],[Fecha inicio real]]-Tbl_PctTrabajoPlanificado[[#This Row],[Fecha Libera Orden]] -> 11 | P8: 46155 | Q8: 46166 | R8: 25012 | S8: 100 | T8: 6 | U8: 6 | V8: Planificado
A9: 21.2026 | B9: 08 INFR SERVIC Y SUMIN DCH | C9: 02 SUMINISTRO ELECTRICO DCH | D9: CHSS-SE | E9: MANT & PLANIF SUMINISTRO ELECTRICO | F9: CGSSERME | G9: 020 | H9: Preventivo Predictivo | I9: =VLOOKUP(Tbl_PctTrabajoPlanificado[[#This Row],[Orden mantenimiento]],Data!$E$2:$H$63,2,FALSE) -> C82 | J9: {=_xlfn.IFS(I9="C81","Pl.Termoelec.Chuq.",I9="C82","Pl.Dist.Energ.Elec",I9="C89","Pl.Mant.Ind.Electr",I9="CO0","Concentradora A0",I9="CO1","Concentradora A1",I9="CO2","Concentradora A2",I9="CB1","SAE Centralizado",I9="C71","Pl.Maestranza.Cent",I9="C72","Pl.Calderería.Cent",I9="C74","CONTRATOS METALMEC",I9="C40","Planif. Refinería",I9="SAPCI","SAPCI",TRUE,"Código no encontrado")} -> Pl.Dist.Energ.Elec | K9: 110447767 | L9: MED.DESCARGA PARC.S/E TCHITACK TR AUX.1 | M9: NOTI CTEC JBFI NLIQ PWF PLAN | N9: PL | O9: =Tbl_PctTrabajoPlanificado[[#This Row],[Fecha inicio real]]-Tbl_PctTrabajoPlanificado[[#This Row],[Fecha Libera Orden]] -> 11 | P9: 46155 | Q9: 46166 | R9: 18845 | S9: 100 | T9: 4 | U9: 4 | V9: Planificado
A10: 21.2026 | B10: 08 INFR SERVIC Y SUMIN DCH | C10: 02 SUMINISTRO ELECTRICO DCH | D10: CHSS-SE | E10: MANT & PLANIF SUMINISTRO ELECTRICO | F10: CGSSERME | G10: 020 | H10: Preventivo Predictivo | I10: =VLOOKUP(Tbl_PctTrabajoPlanificado[[#This Row],[Orden mantenimiento]],Data!$E$2:$H$63,2,FALSE) -> C82 | J10: {=_xlfn.IFS(I10="C81","Pl.Termoelec.Chuq.",I10="C82","Pl.Dist.Energ.Elec",I10="C89","Pl.Mant.Ind.Electr",I10="CO0","Concentradora A0",I10="CO1","Concentradora A1",I10="CO2","Concentradora A2",I10="CB1","SAE Centralizado",I10="C71","Pl.Maestranza.Cent",I10="C72","Pl.Calderería.Cent",I10="C74","CONTRATOS METALMEC",I10="C40","Planif. Refinería",I10="SAPCI","SAPCI",TRUE,"Código no encontrado")} -> Pl.Dist.Energ.Elec | K10: 110447768 | L10: MED.DESCARGA PARC.S/E TCHITACK TR AUX.2 | M10: NOTI CTEC JBFI NLIQ PWF PLAN | N10: PL | O10: =Tbl_PctTrabajoPlanificado[[#This Row],[Fecha inicio real]]-Tbl_PctTrabajoPlanificado[[#This Row],[Fecha Libera Orden]] -> 11 | P10: 46155 | Q10: 46166 | R10: 18845 | S10: 100 | T10: 12 | U10: 12 | V10: Planificado
A11: 21.2026 | B11: 08 INFR SERVIC Y SUMIN DCH | C11: 02 SUMINISTRO ELECTRICO DCH | D11: CHSS-SE | E11: MANT & PLANIF SUMINISTRO ELECTRICO | F11: CGSSERME | G11: 020 | H11: Preventivo Predictivo | I11: =VLOOKUP(Tbl_PctTrabajoPlanificado[[#This Row],[Orden mantenimiento]],Data!$E$2:$H$63,2,FALSE) -> C82 | J11: {=_xlfn.IFS(I11="C81","Pl.Termoelec.Chuq.",I11="C82","Pl.Dist.Energ.Elec",I11="C89","Pl.Mant.Ind.Electr",I11="CO0","Concentradora A0",I11="CO1","Concentradora A1",I11="CO2","Concentradora A2",I11="CB1","SAE Centralizado",I11="C71","Pl.Maestranza.Cent",I11="C72","Pl.Calderería.Cent",I11="C74","CONTRATOS METALMEC",I11="C40","Planif. Refinería",I11="SAPCI","SAPCI",TRUE,"Código no encontrado")} -> Pl.Dist.Energ.Elec | K11: 110468802 | L11: INSPECCION ALIMENTADOR VENTILACIÓN EXTRA | M11: NOTI CTEC JBFI NLIQ PWF PLAN | N11: PL | O11: =Tbl_PctTrabajoPlanificado[[#This Row],[Fecha inicio real]]-Tbl_PctTrabajoPlanificado[[#This Row],[Fecha Libera Orden]] -> 11 | P11: 46155 | Q11: 46166 | R11: 98488 | S11: 100 | T11: 12 | U11: 12 | V11: Planificado
A12: 21.2026 | B12: 08 INFR SERVIC Y SUMIN DCH | C12: 02 SUMINISTRO ELECTRICO DCH | D12: CHSS-SE | E12: MANT & PLANIF SUMINISTRO ELECTRICO | F12: CGSSERME | G12: 025 | H12: Correctivo Planificado | I12: =VLOOKUP(Tbl_PctTrabajoPlanificado[[#This Row],[Orden mantenimiento]],Data!$E$2:$H$63,2,FALSE) -> C82 | J12: {=_xlfn.IFS(I12="C81","Pl.Termoelec.Chuq.",I12="C82","Pl.Dist.Energ.Elec",I12="C89","Pl.Mant.Ind.Electr",I12="CO0","Concentradora A0",I12="CO1","Concentradora A1",I12="CO2","Concentradora A2",I12="CB1","SAE Centralizado",I12="C71","Pl.Maestranza.Cent",I12="C72","Pl.Calderería.Cent",I12="C74","CONTRATOS METALMEC",I12="C40","Planif. Refinería",I12="SAPCI","SAPCI",TRUE,"Código no encontrado")} -> Pl.Dist.Energ.Elec | K12: 110325637 | L12: PRO - Lvtmto Printouts Tchitack 220kV | M12: NOTI CTEC JBFI NLIQ PWF PLAN | N12: PL | O12: =Tbl_PctTrabajoPlanificado[[#This Row],[Fecha inicio real]]-Tbl_PctTrabajoPlanificado[[#This Row],[Fecha Libera Orden]] -> 73 | P12: 46091 | Q12: 46164 | R12: 24474 | S12: 100 | T12: 12 | U12: 12 | V12: Planificado
A13: 21.2026 | B13: 08 INFR SERVIC Y SUMIN DCH | C13: 02 SUMINISTRO ELECTRICO DCH | D13: CHSS-SE | E13: MANT & PLANIF SUMINISTRO ELECTRICO | F13: CGSSERME | G13: 025 | H13: Correctivo Planificado | I13: =VLOOKUP(Tbl_PctTrabajoPlanificado[[#This Row],[Orden mantenimiento]],Data!$E$2:$H$63,2,FALSE) -> C82 | J13: {=_xlfn.IFS(I13="C81","Pl.Termoelec.Chuq.",I13="C82","Pl.Dist.Energ.Elec",I13="C89","Pl.Mant.Ind.Electr",I13="CO0","Concentradora A0",I13="CO1","Concentradora A1",I13="CO2","Concentradora A2",I13="CB1","SAE Centralizado",I13="C71","Pl.Maestranza.Cent",I13="C72","Pl.Calderería.Cent",I13="C74","CONTRATOS METALMEC",I13="C40","Planif. Refinería",I13="SAPCI","SAPCI",TRUE,"Código no encontrado")} -> Pl.Dist.Energ.Elec | K13: 110413484 | L13: INSP ALIMENTADOR 1 VENTILACIÓN INYECCIÓn | M13: NOTI CTEC JBFI NLIQ PWF PLAN | N13: PL | O13: =Tbl_PctTrabajoPlanificado[[#This Row],[Fecha inicio real]]-Tbl_PctTrabajoPlanificado[[#This Row],[Fecha Libera Orden]] -> 10 | P13: 46155 | Q13: 46165 | R13: 10371 | S13: 100 | T13: 44 | U13: 44 | V13: Planificado
... A77: 21.2026 | B77: 08 INFR SERVIC Y SUMIN DCH | C77: 03 PLANTAS DE SUMINISTROS DCH | D77: CHSS-SU | E77: MANT & PLANIF CENTRAL TERMICA SULFUROS | F77: CGSTMRMM | G77: 025 | H77: Correctivo Planificado | I77: =VLOOKUP(Tbl_PctTrabajoPlanificado[[#This Row],[Orden mantenimiento]],Data!$E$2:$H$63,2,FALSE) -> C81 | J77: {=_xlfn.IFS(I77="C81","Pl.Termoelec.Chuq.",I77="C82","Pl.Dist.Energ.Elec",I77="C89","Pl.Mant.Ind.Electr",I77="CO0","Concentradora A0",I77="CO1","Concentradora A1",I77="CO2","Concentradora A2",I77="CB1","SAE Centralizado",I77="C71","Pl.Maestranza.Cent",I77="C72","Pl.Calderería.Cent",I77="C74","CONTRATOS METALMEC",I77="C40","Planif. Refinería",I77="SAPCI","SAPCI",TRUE,"Código no encontrado")} -> Pl.Termoelec.Chuq. | K77: 110499456 | L77: Limpieza de Linea 1 de CAL | M77: NOTI CTEC JBFI NLIQ PWF RESA PLAN | N77: PL | O77: =Tbl_PctTrabajoPlanificado[[#This Row],[Fecha inicio real]]-Tbl_PctTrabajoPlanificado[[#This Row],[Fecha Libera Orden]] -> 11 | P77: 46151 | Q77: 46162 | R77: 40779 | S77: 100 | T77: 36 | U77: 36 | V77: Planificado
A78: 21.2026 | B78: 08 INFR SERVIC Y SUMIN DCH | C78: 03 PLANTAS DE SUMINISTROS DCH | D78: CHSS-SU | E78: MANT & PLANIF CENTRAL TERMICA SULFUROS | F78: CGSTMRMM | G78: 035 | H78: Correctivo No Planificado | I78: =VLOOKUP(Tbl_PctTrabajoPlanificado[[#This Row],[Orden mantenimiento]],Data!$E$2:$H$63,2,FALSE) -> C81 | J78: {=_xlfn.IFS(I78="C81","Pl.Termoelec.Chuq.",I78="C82","Pl.Dist.Energ.Elec",I78="C89","Pl.Mant.Ind.Electr",I78="CO0","Concentradora A0",I78="CO1","Concentradora A1",I78="CO2","Concentradora A2",I78="CB1","SAE Centralizado",I78="C71","Pl.Maestranza.Cent",I78="C72","Pl.Calderería.Cent",I78="C74","CONTRATOS METALMEC",I78="C40","Planif. Refinería",I78="SAPCI","SAPCI",TRUE,"Código no encontrado")} -> Pl.Termoelec.Chuq. | K78: 110513924 | L78: BAC 1 sin protección parte móvil | M78: NOTI CTEC JBFI NLIQ PWF RESA | N78: NP | O78: =Tbl_PctTrabajoPlanificado[[#This Row],[Fecha inicio real]]-Tbl_PctTrabajoPlanificado[[#This Row],[Fecha Libera Orden]] -> 0 | P78: 46160 | Q78: 46160 | R78: # | U78: 1 | V78: Imprevisto
A79: 21.2026 | B79: 08 INFR SERVIC Y SUMIN DCH | C79: 03 PLANTAS DE SUMINISTROS DCH | D79: CHSS-SU | E79: MANT & PLANIF CENTRAL TERMICA SULFUROS | F79: CGSTMRMM | G79: 035 | H79: Correctivo No Planificado | I79: =VLOOKUP(Tbl_PctTrabajoPlanificado[[#This Row],[Orden mantenimiento]],Data!$E$2:$H$63,2,FALSE) -> C81 | J79: {=_xlfn.IFS(I79="C81","Pl.Termoelec.Chuq.",I79="C82","Pl.Dist.Energ.Elec",I79="C89","Pl.Mant.Ind.Electr",I79="CO0","Concentradora A0",I79="CO1","Concentradora A1",I79="CO2","Concentradora A2",I79="CB1","SAE Centralizado",I79="C71","Pl.Maestranza.Cent",I79="C72","Pl.Calderería.Cent",I79="C74","CONTRATOS METALMEC",I79="C40","Planif. Refinería",I79="SAPCI","SAPCI",TRUE,"Código no encontrado")} -> Pl.Termoelec.Chuq. | K79: 110522634 | L79: visor de aceite sucio y bajo nivel | M79: NOTI CTEC JBFI NLIQ PWF RESA | N79: NP | O79: =Tbl_PctTrabajoPlanificado[[#This Row],[Fecha inicio real]]-Tbl_PctTrabajoPlanificado[[#This Row],[Fecha Libera Orden]] -> 5 | P79: 46157 | Q79: 46162 | R79: # | U79: 1 | V79: Imprevisto
A80: 21.2026 | B80: 08 INFR SERVIC Y SUMIN DCH | C80: 03 PLANTAS DE SUMINISTROS DCH | D80: CHSS-SU | E80: MANT & PLANIF CENTRAL TERMICA SULFUROS | F80: CGSTMRMM | G80: 035 | H80: Correctivo No Planificado | I80: =VLOOKUP(Tbl_PctTrabajoPlanificado[[#This Row],[Orden mantenimiento]],Data!$E$2:$H$63,2,FALSE) -> C81 | J80: {=_xlfn.IFS(I80="C81","Pl.Termoelec.Chuq.",I80="C82","Pl.Dist.Energ.Elec",I80="C89","Pl.Mant.Ind.Electr",I80="CO0","Concentradora A0",I80="CO1","Concentradora A1",I80="CO2","Concentradora A2",I80="CB1","SAE Centralizado",I80="C71","Pl.Maestranza.Cent",I80="C72","Pl.Calderería.Cent",I80="C74","CONTRATOS METALMEC",I80="C40","Planif. Refinería",I80="SAPCI","SAPCI",TRUE,"Código no encontrado")} -> Pl.Termoelec.Chuq. | K80: 110525041 | L80: Filtració de agua por válvula | M80: NOTI CTEC JBFI NLIQ PWF RESA | N80: NP | O80: =Tbl_PctTrabajoPlanificado[[#This Row],[Fecha inicio real]]-Tbl_PctTrabajoPlanificado[[#This Row],[Fecha Libera Orden]] -> 0 | P80: 46161 | Q80: 46161 | R80: # | U80: 3 | V80: Imprevisto
A81: 21.2026 | B81: 08 INFR SERVIC Y SUMIN DCH | C81: 03 PLANTAS DE SUMINISTROS DCH | D81: CHSS-SU | E81: MANT & PLANIF CENTRAL TERMICA SULFUROS | F81: CGSTMRMM | G81: 035 | H81: Correctivo No Planificado | I81: =VLOOKUP(Tbl_PctTrabajoPlanificado[[#This Row],[Orden mantenimiento]],Data!$E$2:$H$63,2,FALSE) -> C81 | J81: {=_xlfn.IFS(I81="C81","Pl.Termoelec.Chuq.",I81="C82","Pl.Dist.Energ.Elec",I81="C89","Pl.Mant.Ind.Electr",I81="CO0","Concentradora A0",I81="CO1","Concentradora A1",I81="CO2","Concentradora A2",I81="CB1","SAE Centralizado",I81="C71","Pl.Maestranza.Cent",I81="C72","Pl.Calderería.Cent",I81="C74","CONTRATOS METALMEC",I81="C40","Planif. Refinería",I81="SAPCI","SAPCI",TRUE,"Código no encontrado")} -> Pl.Termoelec.Chuq. | K81: 110531565 | L81: CAMBIO filtro aire C27 ADM SATURADO | M81: NOTI CTEC JBFI NLIQ PWF RESA | N81: NP | O81: =Tbl_PctTrabajoPlanificado[[#This Row],[Fecha inicio real]]-Tbl_PctTrabajoPlanificado[[#This Row],[Fecha Libera Orden]] -> 0 | P81: 46160 | Q81: 46160 | R81: # | U81: 5 | V81: Imprevisto
A82: 21.2026 | B82: 08 INFR SERVIC Y SUMIN DCH | C82: 03 PLANTAS DE SUMINISTROS DCH | D82: CHSS-SU | E82: MANT & PLANIF CENTRAL TERMICA SULFUROS | F82: CGSTMRMM | G82: 035 | H82: Correctivo No Planificado | I82: =VLOOKUP(Tbl_PctTrabajoPlanificado[[#This Row],[Orden mantenimiento]],Data!$E$2:$H$63,2,FALSE) -> C81 | J82: {=_xlfn.IFS(I82="C81","Pl.Termoelec.Chuq.",I82="C82","Pl.Dist.Energ.Elec",I82="C89","Pl.Mant.Ind.Electr",I82="CO0","Concentradora A0",I82="CO1","Concentradora A1",I82="CO2","Concentradora A2",I82="CB1","SAE Centralizado",I82="C71","Pl.Maestranza.Cent",I82="C72","Pl.Calderería.Cent",I82="C74","CONTRATOS METALMEC",I82="C40","Planif. Refinería",I82="SAPCI","SAPCI",TRUE,"Código no encontrado")} -> Pl.Termoelec.Chuq. | K82: 110537056 | L82: Cambio llave de corte tubo nivel | M82: NOTI CTEC JBFI NLIQ PWF | N82: NP | O82: =Tbl_PctTrabajoPlanificado[[#This Row],[Fecha inicio real]]-Tbl_PctTrabajoPlanificado[[#This Row],[Fecha Libera Orden]] -> 0 | P82: 46161 | Q82: 46161 | R82: # | U82: 4 | V82: Imprevisto
A83: 21.2026 | B83: 08 INFR SERVIC Y SUMIN DCH | C83: 03 PLANTAS DE SUMINISTROS DCH | D83: CHSS-SU | E83: MANT & PLANIF CENTRAL TERMICA SULFUROS | F83: CGSTMRMM | G83: 035 | H83: Correctivo No Planificado | I83: =VLOOKUP(Tbl_PctTrabajoPlanificado[[#This Row],[Orden mantenimiento]],Data!$E$2:$H$63,2,FALSE) -> C81 | J83: {=_xlfn.IFS(I83="C81","Pl.Termoelec.Chuq.",I83="C82","Pl.Dist.Energ.Elec",I83="C89","Pl.Mant.Ind.Electr",I83="CO0","Concentradora A0",I83="CO1","Concentradora A1",I83="CO2","Concentradora A2",I83="CB1","SAE Centralizado",I83="C71","Pl.Maestranza.Cent",I83="C72","Pl.Calderería.Cent",I83="C74","CONTRATOS METALMEC",I83="C40","Planif. Refinería",I83="SAPCI","SAPCI",TRUE,"Código no encontrado")} -> Pl.Termoelec.Chuq. | K83: 110537056 | L83: Cambio llave de corte tubo nivel | M83: NOTI CTEC JBFI NLIQ PWF RESA | N83: NP | O83: =Tbl_PctTrabajoPlanificado[[#This Row],[Fecha inicio real]]-Tbl_PctTrabajoPlanificado[[#This Row],[Fecha Libera Orden]] -> 0 | P83: 46161 | Q83: 46161 | R83: # | U83: 1 | V83: Imprevisto
A84: 21.2026 | B84: 08 INFR SERVIC Y SUMIN DCH | C84: 03 PLANTAS DE SUMINISTROS DCH | D84: CHSS-SU | E84: MANT & PLANIF CENTRAL TERMICA SULFUROS | F84: CGSTMRMM | G84: 035 | H84: Correctivo No Planificado | I84: =VLOOKUP(Tbl_PctTrabajoPlanificado[[#This Row],[Orden mantenimiento]],Data!$E$2:$H$63,2,FALSE) -> C81 | J84: {=_xlfn.IFS(I84="C81","Pl.Termoelec.Chuq.",I84="C82","Pl.Dist.Energ.Elec",I84="C89","Pl.Mant.Ind.Electr",I84="CO0","Concentradora A0",I84="CO1","Concentradora A1",I84="CO2","Concentradora A2",I84="CB1","SAE Centralizado",I84="C71","Pl.Maestranza.Cent",I84="C72","Pl.Calderería.Cent",I84="C74","CONTRATOS METALMEC",I84="C40","Planif. Refinería",I84="SAPCI","SAPCI",TRUE,"Código no encontrado")} -> Pl.Termoelec.Chuq. | K84: 110543322 | L84: Revision C2: V/v venteo trabada | M84: NOTI CTEC JBFI NLIQ PWF RESA | N84: NP | O84: =Tbl_PctTrabajoPlanificado[[#This Row],[Fecha inicio real]]-Tbl_PctTrabajoPlanificado[[#This Row],[Fecha Libera Orden]] -> 0 | P84: 46161 | Q84: 46161 | R84: # | U84: 2 | V84: Imprevisto
A85: 21.2026 | B85: 08 INFR SERVIC Y SUMIN DCH | C85: 03 PLANTAS DE SUMINISTROS DCH | D85: CHSS-SU | E85: MANT & PLANIF CENTRAL TERMICA SULFUROS | F85: CGSTMRMM | G85: 035 | H85: Correctivo No Planificado | I85: =VLOOKUP(Tbl_PctTrabajoPlanificado[[#This Row],[Orden mantenimiento]],Data!$E$2:$H$63,2,FALSE) -> C81 | J85: {=_xlfn.IFS(I85="C81","Pl.Termoelec.Chuq.",I85="C82","Pl.Dist.Energ.Elec",I85="C89","Pl.Mant.Ind.Electr",I85="CO0","Concentradora A0",I85="CO1","Concentradora A1",I85="CO2","Concentradora A2",I85="CB1","SAE Centralizado",I85="C71","Pl.Maestranza.Cent",I85="C72","Pl.Calderería.Cent",I85="C74","CONTRATOS METALMEC",I85="C40","Planif. Refinería",I85="SAPCI","SAPCI",TRUE,"Código no encontrado")} -> Pl.Termoelec.Chuq. | K85: 110543928 | L85: Revision C3 Bba ENF2 ruido y alto amp | M85: NOTI CTEC JBFI NLIQ PWF RESA | N85: NP | O85: =Tbl_PctTrabajoPlanificado[[#This Row],[Fecha inicio real]]-Tbl_PctTrabajoPlanificado[[#This Row],[Fecha Libera Orden]] -> 0 | P85: 46164 | Q85: 46164 | R85: # | U85: 5.5 | V85: Imprevisto
A86: 21.2026 | B86: 08 INFR SERVIC Y SUMIN DCH | C86: 03 PLANTAS DE SUMINISTROS DCH | D86: CHSS-SU | E86: MANT & PLANIF CENTRAL TERMICA SULFUROS | F86: CGSTMRMM | G86: 035 | H86: Correctivo No Planificado | I86: =VLOOKUP(Tbl_PctTrabajoPlanificado[[#This Row],[Orden mantenimiento]],Data!$E$2:$H$63,2,FALSE) -> C81 | J86: {=_xlfn.IFS(I86="C81","Pl.Termoelec.Chuq.",I86="C82","Pl.Dist.Energ.Elec",I86="C89","Pl.Mant.Ind.Electr",I86="CO0","Concentradora A0",I86="CO1","Concentradora A1",I86="CO2","Concentradora A2",I86="CB1","SAE Centralizado",I86="C71","Pl.Maestranza.Cent",I86="C72","Pl.Calderería.Cent",I86="C74","CONTRATOS METALMEC",I86="C40","Planif. Refinería",I86="SAPCI","SAPCI",TRUE,"Código no encontrado")} -> Pl.Termoelec.Chuq. | K86: 110544879 | L86: Línea Despiche ciclón rota | M86: NOTI CTEC JBFI NLIQ PWF RESA | N86: NP | O86: =Tbl_PctTrabajoPlanificado[[#This Row],[Fecha inicio real]]-Tbl_PctTrabajoPlanificado[[#This Row],[Fecha Libera Orden]] -> -1 | P86: 46164 | Q86: 46163 | R86: # | U86: 3 | V86: Imprevisto
A87: 21.2026 | B87: 08 INFR SERVIC Y SUMIN DCH | C87: 03 PLANTAS DE SUMINISTROS DCH | D87: CHSS-SU | E87: MANT & PLANIF CENTRAL TERMICA SULFUROS | F87: CGSTMRMM | G87: 035 | H87: Correctivo No Planificado | I87: =VLOOKUP(Tbl_PctTrabajoPlanificado[[#This Row],[Orden mantenimiento]],Data!$E$2:$H$63,2,FALSE) -> C81 | J87: {=_xlfn.IFS(I87="C81","Pl.Termoelec.Chuq.",I87="C82","Pl.Dist.Energ.Elec",I87="C89","Pl.Mant.Ind.Electr",I87="CO0","Concentradora A0",I87="CO1","Concentradora A1",I87="CO2","Concentradora A2",I87="CB1","SAE Centralizado",I87="C71","Pl.Maestranza.Cent",I87="C72","Pl.Calderería.Cent",I87="C74","CONTRATOS METALMEC",I87="C40","Planif. Refinería",I87="SAPCI","SAPCI",TRUE,"Código no encontrado")} -> Pl.Termoelec.Chuq. | K87: 110547174 | L87: Habilitacion de bomba BAC 3 | M87: NOTI CTEC JBFI NLIQ PWF RESA | N87: NP | O87: =Tbl_PctTrabajoPlanificado[[#This Row],[Fecha inicio real]]-Tbl_PctTrabajoPlanificado[[#This Row],[Fecha Libera Orden]] -> 0 | P87: 46166 | Q87: 46166 | R87: # | U87: 4 | V87: Imprevisto
A88: 21.2026 | B88: 08 INFR SERVIC Y SUMIN DCH | C88: 03 PLANTAS DE SUMINISTROS DCH | D88: CHSS-SU | E88: MANT & PLANIF CENTRAL TERMICA SULFUROS | F88: CGSTMRMM | G88: 035 | H88: Correctivo No Planificado | I88: =VLOOKUP(Tbl_PctTrabajoPlanificado[[#This Row],[Orden mantenimiento]],Data!$E$2:$H$63,2,FALSE) -> C81 | J88: {=_xlfn.IFS(I88="C81","Pl.Termoelec.Chuq.",I88="C82","Pl.Dist.Energ.Elec",I88="C89","Pl.Mant.Ind.Electr",I88="CO0","Concentradora A0",I88="CO1","Concentradora A1",I88="CO2","Concentradora A2",I88="CB1","SAE Centralizado",I88="C71","Pl.Maestranza.Cent",I88="C72","Pl.Calderería.Cent",I88="C74","CONTRATOS METALMEC",I88="C40","Planif. Refinería",I88="SAPCI","SAPCI",TRUE,"Código no encontrado")} -> Pl.Termoelec.Chuq. | K88: 110547304 | L88: Filtracion de vapor en purga continua | M88: NOTI CTEC JBFI NLIQ PWF RESA | N88: NP | O88: =Tbl_PctTrabajoPlanificado[[#This Row],[Fecha inicio real]]-Tbl_PctTrabajoPlanificado[[#This Row],[Fecha Libera Orden]] -> -1 | P88: 46164 | Q88: 46163 | R88: # | U88: 3 | V88: Imprevisto
A89: 21.2026 | B89: 08 INFR SERVIC Y SUMIN DCH | C89: 03 PLANTAS DE SUMINISTROS DCH | D89: CHSS-SU | E89: MANT & PLANIF CENTRAL TERMICA SULFUROS | F89: CGSTMRMM | G89: 035 | H89: Correctivo No Planificado | I89: =VLOOKUP(Tbl_PctTrabajoPlanificado[[#This Row],[Orden mantenimiento]],Data!$E$2:$H$63,2,FALSE) -> C81 | J89: {=_xlfn.IFS(I89="C81","Pl.Termoelec.Chuq.",I89="C82","Pl.Dist.Energ.Elec",I89="C89","Pl.Mant.Ind.Electr",I89="CO0","Concentradora A0",I89="CO1","Concentradora A1",I89="CO2","Concentradora A2",I89="CB1","SAE Centralizado",I89="C71","Pl.Maestranza.Cent",I89="C72","Pl.Calderería.Cent",I89="C74","CONTRATOS METALMEC",I89="C40","Planif. Refinería",I89="SAPCI","SAPCI",TRUE,"Código no encontrado")} -> Pl.Termoelec.Chuq. | K89: 110549479 | L89: Lubricador automático en falla | M89: NOTI CTEC JBFI NLIQ PWF RESA | N89: NP | O89: =Tbl_PctTrabajoPlanificado[[#This Row],[Fecha inicio real]]-Tbl_PctTrabajoPlanificado[[#This Row],[Fecha Libera Orden]] -> 0 | P89: 46163 | Q89: 46163 | R89: # | U89: 0.2 | V89: Imprevisto
... A91: 21.2026 | B91: 08 INFR SERVIC Y SUMIN DCH | C91: 03 PLANTAS DE SUMINISTROS DCH | D91: CHSS-SU | E91: MANT & PLANIF CENTRAL TERMICA SULFUROS | F91: CGSTMRMM | G91: 035 | H91: Correctivo No Planificado | I91: =VLOOKUP(Tbl_PctTrabajoPlanificado[[#This Row],[Orden mantenimiento]],Data!$E$2:$H$63,2,FALSE) -> C81 | J91: {=_xlfn.IFS(I91="C81","Pl.Termoelec.Chuq.",I91="C82","Pl.Dist.Energ.Elec",I91="C89","Pl.Mant.Ind.Electr",I91="CO0","Concentradora A0",I91="CO1","Concentradora A1",I91="CO2","Concentradora A2",I91="CB1","SAE Centralizado",I91="C71","Pl.Maestranza.Cent",I91="C72","Pl.Calderería.Cent",I91="C74","CONTRATOS METALMEC",I91="C40","Planif. Refinería",I91="SAPCI","SAPCI",TRUE,"Código no encontrado")} -> Pl.Termoelec.Chuq. | K91: 110554318 | L91: Falla lubricador automático | M91: NOTI JBFI LIB. NLIQ PWF RESA | N91: NP | O91: =Tbl_PctTrabajoPlanificado[[#This Row],[Fecha inicio real]]-Tbl_PctTrabajoPlanificado[[#This Row],[Fecha Libera Orden]] -> 0 | P91: 46166 | Q91: 46166 | R91: # | U91: 0.2 | V91: Imprevisto
A92: 21.2026 | B92: 08 INFR SERVIC Y SUMIN DCH | C92: 99 ESENCIALES INFRA. SERV. DCH | D92: 02 GRUAS INFRA DCH | E92: MANT & PLANIF CENTRAL TERMICA SULFUROS | F92: CGSTMRMM | G92: 010 | H92: Preventivo Sistemático | I92: =VLOOKUP(Tbl_PctTrabajoPlanificado[[#This Row],[Orden mantenimiento]],Data!$E$2:$H$63,2,FALSE) -> C81 | J92: {=_xlfn.IFS(I92="C81","Pl.Termoelec.Chuq.",I92="C82","Pl.Dist.Energ.Elec",I92="C89","Pl.Mant.Ind.Electr",I92="CO0","Concentradora A0",I92="CO1","Concentradora A1",I92="CO2","Concentradora A2",I92="CB1","SAE Centralizado",I92="C71","Pl.Maestranza.Cent",I92="C72","Pl.Calderería.Cent",I92="C74","CONTRATOS METALMEC",I92="C40","Planif. Refinería",I92="SAPCI","SAPCI",TRUE,"Código no encontrado")} -> Pl.Termoelec.Chuq. | K92: 110448004 | L92: MRT 4S MEC MTTO PUENTE GRUA SOPLADORES | M92: NOTI JBFI LIB. NLIQ PLAN PWF RESA | N92: PL | O92: =Tbl_PctTrabajoPlanificado[[#This Row],[Fecha inicio real]]-Tbl_PctTrabajoPlanificado[[#This Row],[Fecha Libera Orden]] -> 18 | P92: 46147 | Q92: 46165 | R92: 98123 | S92: 100 | T92: 16.5 | U92: 16.5 | V92: Planificado
A93: 21.2026 | B93: 08 INFR SERVIC Y SUMIN DCH | C93: 99 ESENCIALES INFRA. SERV. DCH | D93: 03 SIST. C.INCENDIO INFRA DCH | E93: MANT & PLANIF SUMINISTRO ELECTRICO | F93: CGSSERME | G93: 010 | H93: Preventivo Sistemático | I93: =VLOOKUP(Tbl_PctTrabajoPlanificado[[#This Row],[Orden mantenimiento]],Data!$E$2:$H$63,2,FALSE) -> C82 | J93: {=_xlfn.IFS(I93="C81","Pl.Termoelec.Chuq.",I93="C82","Pl.Dist.Energ.Elec",I93="C89","Pl.Mant.Ind.Electr",I93="CO0","Concentradora A0",I93="CO1","Concentradora A1",I93="CO2","Concentradora A2",I93="CB1","SAE Centralizado",I93="C71","Pl.Maestranza.Cent",I93="C72","Pl.Calderería.Cent",I93="C74","CONTRATOS METALMEC",I93="C40","Planif. Refinería",I93="SAPCI","SAPCI",TRUE,"Código no encontrado")} -> Pl.Dist.Energ.Elec | K93: 110500459 | L93: INSPECCIO SAPCI S/E SOPLADORES GIS 100KV | M93: NOTI CTEC JBFI NLIQ PWF RESA PLAN | N93: PL | O93: =Tbl_PctTrabajoPlanificado[[#This Row],[Fecha inicio real]]-Tbl_PctTrabajoPlanificado[[#This Row],[Fecha Libera Orden]] -> 10 | P93: 46155 | Q93: 46165 | R93: 98157 | S93: 100 | T93: 3 | U93: 3 | V93: Planificado
A94: 21.2026 | B94: 08 INFR SERVIC Y SUMIN DCH | C94: 99 ESENCIALES INFRA. SERV. DCH | D94: 03 SIST. C.INCENDIO INFRA DCH | E94: MANT & PLANIF SUMINISTRO ELECTRICO | F94: CGSSERME | G94: 020 | H94: Preventivo Predictivo | I94: =VLOOKUP(Tbl_PctTrabajoPlanificado[[#This Row],[Orden mantenimiento]],Data!$E$2:$H$63,2,FALSE) -> C82 | J94: {=_xlfn.IFS(I94="C81","Pl.Termoelec.Chuq.",I94="C82","Pl.Dist.Energ.Elec",I94="C89","Pl.Mant.Ind.Electr",I94="CO0","Concentradora A0",I94="CO1","Concentradora A1",I94="CO2","Concentradora A2",I94="CB1","SAE Centralizado",I94="C71","Pl.Maestranza.Cent",I94="C72","Pl.Calderería.Cent",I94="C74","CONTRATOS METALMEC",I94="C40","Planif. Refinería",I94="SAPCI","SAPCI",TRUE,"Código no encontrado")} -> Pl.Dist.Energ.Elec | K94: 110495171 | L94: INSPECCIÓN SAPCI S/E K1 SALA CONTROL | M94: NOTI CTEC JBFI NLIQ PWF PLAN | N94: PL | O94: =Tbl_PctTrabajoPlanificado[[#This Row],[Fecha inicio real]]-Tbl_PctTrabajoPlanificado[[#This Row],[Fecha Libera Orden]] -> 8 | P94: 46155 | Q94: 46163 | R94: 98157 | S94: 100 | T94: 3 | U94: 3 | V94: Planificado
A95: 21.2026 | B95: 08 INFR SERVIC Y SUMIN DCH | C95: 99 ESENCIALES INFRA. SERV. DCH | D95: 03 SIST. C.INCENDIO INFRA DCH | E95: MANT & PLANIF SUMINISTRO ELECTRICO | F95: CGSSERME | G95: 020 | H95: Preventivo Predictivo | I95: =VLOOKUP(Tbl_PctTrabajoPlanificado[[#This Row],[Orden mantenimiento]],Data!$E$2:$H$63,2,FALSE) -> C82 | J95: {=_xlfn.IFS(I95="C81","Pl.Termoelec.Chuq.",I95="C82","Pl.Dist.Energ.Elec",I95="C89","Pl.Mant.Ind.Electr",I95="CO0","Concentradora A0",I95="CO1","Concentradora A1",I95="CO2","Concentradora A2",I95="CB1","SAE Centralizado",I95="C71","Pl.Maestranza.Cent",I95="C72","Pl.Calderería.Cent",I95="C74","CONTRATOS METALMEC",I95="C40","Planif. Refinería",I95="SAPCI","SAPCI",TRUE,"Código no encontrado")} -> Pl.Dist.Energ.Elec | K95: 110495172 | L95: INSPECCIÓN SAPCI S/E TCHITACK GIS 13,8KV | M95: NOTI CTEC JBFI NLIQ PWF RESA PLAN | N95: PL | O95: =Tbl_PctTrabajoPlanificado[[#This Row],[Fecha inicio real]]-Tbl_PctTrabajoPlanificado[[#This Row],[Fecha Libera Orden]] -> 9 | P95: 46155 | Q95: 46164 | R95: 98157 | S95: 100 | T95: 3 | U95: 3 | V95: Planificado
A96: 21.2026 | B96: 08 INFR SERVIC Y SUMIN DCH | C96: 99 ESENCIALES INFRA. SERV. DCH | D96: 05 RESPAL. E.ELEC. INFRA DCH | E96: MANT & PLANIF SUMINISTRO ELECTRICO | F96: CGSSERME | G96: 025 | H96: Correctivo Planificado | I96: =VLOOKUP(Tbl_PctTrabajoPlanificado[[#This Row],[Orden mantenimiento]],Data!$E$2:$H$63,2,FALSE) -> C82 | J96: {=_xlfn.IFS(I96="C81","Pl.Termoelec.Chuq.",I96="C82","Pl.Dist.Energ.Elec",I96="C89","Pl.Mant.Ind.Electr",I96="CO0","Concentradora A0",I96="CO1","Concentradora A1",I96="CO2","Concentradora A2",I96="CB1","SAE Centralizado",I96="C71","Pl.Maestranza.Cent",I96="C72","Pl.Calderería.Cent",I96="C74","CONTRATOS METALMEC",I96="C40","Planif. Refinería",I96="SAPCI","SAPCI",TRUE,"Código no encontrado")} -> Pl.Dist.Energ.Elec | K96: 110440236 | L96: STN CAMBIO EXTINTOR UPS N°2 SCADA S/E A | M96: NOTI CTEC JBFI NLIQ PWF RESA PLAN | N96: PL | O96: =Tbl_PctTrabajoPlanificado[[#This Row],[Fecha inicio real]]-Tbl_PctTrabajoPlanificado[[#This Row],[Fecha Libera Orden]] -> 25 | P96: 46137 | Q96: 46162 | R96: 98949 | S96: 100 | T96: 2 | U96: 2 | V96: Planificado
A97: 21.2026 | B97: 08 INFR SERVIC Y SUMIN DCH | C97: 99 ESENCIALES INFRA. SERV. DCH | D97: 05 RESPAL. E.ELEC. INFRA DCH | E97: MANT & PLANIF SUMINISTRO ELECTRICO | F97: CGSSERME | G97: 025 | H97: Correctivo Planificado | I97: =VLOOKUP(Tbl_PctTrabajoPlanificado[[#This Row],[Orden mantenimiento]],Data!$E$2:$H$63,2,FALSE) -> C82 | J97: {=_xlfn.IFS(I97="C81","Pl.Termoelec.Chuq.",I97="C82","Pl.Dist.Energ.Elec",I97="C89","Pl.Mant.Ind.Electr",I97="CO0","Concentradora A0",I97="CO1","Concentradora A1",I97="CO2","Concentradora A2",I97="CB1","SAE Centralizado",I97="C71","Pl.Maestranza.Cent",I97="C72","Pl.Calderería.Cent",I97="C74","CONTRATOS METALMEC",I97="C40","Planif. Refinería",I97="SAPCI","SAPCI",TRUE,"Código no encontrado")} -> Pl.Dist.Energ.Elec | K97: 110440238 | L97: STN CAMBIO EXTINTOR UPS N°1 SCADA S/E A | M97: NOTI CTEC JBFI NLIQ PWF RESA PLAN | N97: PL | O97: =Tbl_PctTrabajoPlanificado[[#This Row],[Fecha inicio real]]-Tbl_PctTrabajoPlanificado[[#This Row],[Fecha Libera Orden]] -> 25 | P97: 46137 | Q97: 46162 | R97: 98949 | S97: 100 | T97: 2 | U97: 2 | V97: Planificado
