Workbook

Sheet Data
A1: Grupo planificación | B1: Clase de orden | C1: Clase actividad PM | D1: Aviso | E1: Orden | F1: Grupo planificación | G1: Texto breve | H1: Pto.tbjo.responsable | I1: Ubicación técnica | J1: Denom.ubic.técnica | K1: Status de sistema | L1: Status de usuario | M1: Fecha inicio extrema | N1: Fecha fin extrema | O1: Autor | P1: Modificado por | Q1: Fecha liber.real | R1: Fecha de creación | S1: Inicio programado | T1: Fecha inicio real | U1: Fecha fin real | V1: Plan mant.preventivo | W1: Posición mantenim. | X1: Costes tot.reales | Y1: Tota general (plan)
A2: C81 | B2: NP | C2: 035 | D2: 29844068 | E2: 110324133 | F2: C81 | G2: INST BIOMETRICO sala 7 | H2: CGSTMRMM | I2: CHSS-SU-CTS-SAL-SLT07 | J2: SALA ELECTRICA Nº7 CALDERAS COMPACTAS | K2: CTEC NOTI DOCU IMOP JBFI KKMP PREC | L2: TRAT | M2: 46108 | N2: 46108 | O2: MJAIM002 | P2: CMEND008 | Q2: 46108 | R2: 46091 | S2: 46108 | T2: 46156 | U2: 46156 | X2: 0.02 | Y2: 0.02
A3: C81 | B3: NP | C3: 035 | D3: 30030375 | E3: 110505267 | F3: C81 | G3: Visor sucio de descanso | H3: CGSTMRMM | I3: CHSS-SU-CTS-A90-COS10-SMO-MOTR | J3: MOTOR ELÉCTRICO | K3: CTEC NOTI DOCU IMOP JBFI KKMP PREC | L3: TBTR | M3: 46150 | N3: 46150 | O3: VTORR010 | P3: CMEND008 | Q3: 46149 | R3: 46149 | S3: 46150 | T3: 46154 | U3: 46154 | X3: 267.18 | Y3: 267.18
A4: C81 | B4: PL | C4: 025 | D4: 29978722 | E4: 110457406 | F4: C81 | G4: (Q) TRAB PREVIOS MTTO 6M COMP 20 | H4: CGSTMRMM | I4: CHSS-SU-CTS-A30-CAP20 | J4: COMPRESOR CENTRIFUGO 20 | K4: LIB. NOTP DOCU IMOP KKMP PREC PROG | L4: TRAT | M4: 46151 | N4: 46152 | O4: VVERG011 | P4: MJAIM002 | Q4: 46135 | R4: 46134 | S4: 46151 | T4: 46151 | X4: 2333.45 | Y4: 2333.52
A5: C81 | B5: NP | C5: 035 | D5: 30017733 | E5: 110493464 | F5: C81 | G5: COMP 29 -CAMBIO DE ENFRIADERA | H5: CGSTMRMM | I5: CHSS-SU-CTS-A30-CAP29-SEN-ENFA | J5: ENFRIADERA DE AGUA | K5: LIB. NOTI DOCU IMOP JBFI KKMP PREC | L5: TRAT | M5: 46151 | N5: 46151 | O5: MJAIM002 | P5: MJAIM002 | Q5: 46151 | R5: 46146 | S5: 46151 | T5: 46151 | U5: 46154 | X5: 0.05 | Y5: 0.05
A6: C81 | B6: PL | C6: 025 | D6: 28514273 | E6: 109037716 | F6: C81 | G6: Cambio de calefactor de aceite Comp N°2 | H6: CGSTMRMM | I6: CHSS-SU-CTS-A90-COS02-SLU-CALF | J6: CALEFACTOR DE ACEITE | K6: LIB. NOTI DOCU IMOP JBFI MACO MOVM PREC* | L6: TBTR | M6: 46153 | N6: 46153 | O6: TRAMI002 | P6: MJAIM002 | Q6: 45680 | R6: 45679 | S6: 46153 | T6: 46153 | U6: 46159 | X6: 6629.25 | Y6: 6629.25
A7: C81 | B7: PL | C7: 025 | D7: 28578506 | E7: 109098394 | F7: C81 | G7: Cambio filtros de admisión C-1 | H7: CGSTMRMM | I7: CHSS-SU-CTS-A90-COS01 | J7: COMPRESOR CENTRIFUGO ELLIOTT 01 | K7: LIB. NOTI DOCU IMOP JBFI MACO MOVM PREC* | L7: TBTR | M7: 46153 | N7: 46153 | O7: TRAMI002 | P7: MJAIM002 | Q7: 45700 | R7: 45700 | S7: 46153 | T7: 46153 | U7: 46159 | X7: 7683.93 | Y7: 8026.39
A8: C82 | B8: PL | C8: 020 | D8: 29850364 | E8: 110330383 | F8: C82 | G8: Insp. 4M S/E Dist. 13.8 kV Refinería | H8: CGSSERME | I8: CDEE-SED | J8: SUBESTACIONES DE DISTRIBUCION | K8: CTEC NOTI DOCU IMOP JBFI KKMP PREC PROG | L8: TBTR | M8: 46153 | N8: 46154 | O8: IP1020260312 | P8: JGALA017 | Q8: 46139 | R8: 46093 | S8: 46153 | T8: 46153 | U8: 46154 | V8: 165531 | W8: 299345 | X8: 1812.8 | Y8: 1812.8
A9: C81 | B9: PL | C9: 010 | D9: 29956150 | E9: 110432882 | F9: C81 | G9: MRT 1S MEC LIMPIEZA MOLINO HARDINGE 1 | H9: CGSTMRMM | I9: CHSS-SU-PHC-MMH-MLH01 | J9: MOLINO HARDINGE Nº1 | K9: CTEC NOTI DOCU IMOP JBFI KKMP PREC PROG | L9: TRAT | M9: 46153 | N9: 46153 | O9: IP1020260414 | P9: CMEND008 | Q9: 46145 | R9: 46126 | S9: 46153 | T9: 46153 | U9: 46153 | V9: 139516 | W9: 251835 | X9: 89.11 | Y9: 89.11
A10: C81 | B10: PL | C10: 010 | D10: 29956160 | E10: 110432892 | F10: C81 | G10: MRT 1S MTTO CORREA 132 | H10: CGSTMRMM | I10: CHSS-SU-PHC-TCH-CT132 | J10: CORREA TRANSPORTADORA Nº132 | K10: CTEC NOTI DOCU IMOP JBFI KKMP PREC PROG | L10: TBTR | M10: 46153 | N10: 46153 | O10: IP1020260414 | P10: CMEND008 | Q10: 46145 | R10: 46126 | S10: 46153 | T10: 46153 | U10: 46153 | V10: 225688 | W10: 419098 | X10: 267.35 | Y10: 267.35
A11: C81 | B11: PL | C11: 010 | D11: 29956164 | E11: 110432896 | F11: C81 | G11: MRT 1S LIMPIEZA FILTRO DE MANGA | H11: CGSTMRMM | I11: CHSS-SU-PHC-SAL-SIL01 | J11: SILO 01 | K11: CTEC NOTI DOCU IMOP JBFI KKMP PREC PROG | L11: TRAT | M11: 46153 | N11: 46153 | O11: IP1020260414 | P11: CMEND008 | Q11: 46145 | R11: 46126 | S11: 46153 | T11: 46153 | U11: 46153 | V11: 225920 | W11: 419420 | X11: 0.06 | Y11: 0.06
A12: C82 | B12: PL | C12: 020 | D12: 29963521 | E12: 110439860 | F12: C82 | G12: INSPECCION SISTEMA SAPCI S/E KM6 | H12: CGSSERME | I12: CHSS-SE-SUP-SK6-SAPCI | J12: SISTEMA SAPCI S/E KM6 | K12: CTEC NOTI DOCU IMOP JBFI KKMP PREC PROG | L12: TBTR | M12: 46153 | N12: 46153 | O12: IP1020260416 | P12: CURQU002 | Q12: 46139 | R12: 46128 | S12: 46153 | T12: 46153 | U12: 46153 | V12: 226513 | W12: 419560 | X12: 82.4 | Y12: 82.4
A13: C82 | B13: PL | C13: 020 | D13: 29963522 | E13: 110439861 | F13: C82 | G13: INSPECCION SISTEMA SAPCI S/E 10 | H13: CGSSERME | I13: CHSS-SE-SUP-SPA-SBE10-SAP | J13: SISTEMA SAPCI S/E 10 | K13: CTEC NOTI DOCU IMOP JBFI KKMP PREC PROG | L13: TBTR | M13: 46153 | N13: 46153 | O13: IP1020260416 | P13: CURQU002 | Q13: 46139 | R13: 46128 | S13: 46153 | T13: 46153 | U13: 46153 | V13: 226514 | W13: 419561 | X13: 82.4 | Y13: 82.4
A14: C81 | B14: PL | C14: 025 | D14: 29999833 | E14: 110475348 | F14: C81 | G14: 3M MTTO BOMBA CIRCULADORA N°2 | H14: CGSTMRMM | I14: CHSS-SU-CTS-ENF-BCPV2 | J14: BOMBA CIRCULADORA 2 VAPOR SOBRANTE | K14: CTEC NOTI DOCU IMOP JBFI KKMP PREC PROG | L14: TBTR | M14: 46153 | N14: 46153 | O14: VVERG011 | P14: CMEND008 | Q14: 46145 | R14: 46140 | S14: 46153 | T14: 46158 | U14: 46158 | X14: 561.07 | Y14: 543.28
A15: C81 | B15: PL | C15: 025 | D15: 29999836 | E15: 110475355 | F15: C81 | G15: COMP 20 -CAMBIO DE ENFRIADERA. | H15: CGSTMRMM | I15: CHSS-SU-CTS-A30-CAP20 | J15: COMPRESOR CENTRIFUGO 20 | K15: LIB. NOTI DOCU IMOP JBFI MACO MOVM PREC* | L15: TRAT | M15: 46153 | N15: 46157 | O15: VVERG011 | P15: LVEGA028 | Q15: 46142 | R15: 46140 | S15: 46153 | T15: 46154 | U15: 46158 | X15: 9017.23 | Y15: 9788.38
A16: C81 | B16: PL | C16: 025 | D16: 30000012 | E16: 110475425 | F16: C81 | G16: 48M MTTO COMPRESOR 08 | H16: CGSTMRMM | I16: CHSS-SU-CTS-A90-COS08 | J16: COMPRESOR CENTRIFUGO ELLIOTT 08 | K16: LIB. NOTP DOCU IMOP KKMP PREC PROG | L16: TRAT | M16: 46153 | N16: 46157 | O16: VVERG011 | P16: MJAIM002 | Q16: 46145 | R16: 46140 | S16: 46153 | T16: 46154 | X16: 0.66 | Y16: 2494.34
A17: C81 | B17: PL | C17: 010 | D17: 30003321 | E17: 110478068 | F17: C81 | G17: MRT 6M MTTO COMPRESOR N°20 | H17: CGSTMRMM | I17: CHSS-SU-CTS-A90-CAP20 | J17: COMPRESOR CENTRIFUGO 20 | K17: LIB. NOTP DOCU IMOP KKMP PREC PROG | L17: TRAT | M17: 46153 | N17: 46157 | O17: IP1020260429 | P17: MREINES | Q17: 46145 | R17: 46141 | S17: 46153 | T17: 46151 | V17: 222731 | W17: 412728 | X17: 4185.97 | Y17: 5878.11
A18: C81 | B18: PL | C18: 025 | D18: 30006694 | E18: 110481437 | F18: C81 | G18: (Q) Limpieza de Linea 10 de CAL | H18: CGSTMRMM | I18: CHSS-SU-PHC-TLC-SPIVV | J18: SISTEMA PIPING Y VALVULAS | K18: LIB. NOTP DOCU IMOP KKMP PREC PROG | L18: TRAT | M18: 46153 | N18: 46155 | O18: VVERG011 | P18: MJAIM002 | Q18: 46145 | R18: 46142 | S18: 46153 | T18: 46153 | X18: 0.22 | Y18: 0.28
A19: C81 | B19: NP | C19: 035 | D19: 30029647 | E19: 110505271 | F19: C81 | G19: Rellenar nivel de aceite carter | H19: CGSTMRMM | I19: CHSS-SU-CTS-A90-COS24-SLU-CART | J19: CARTER DE ACEITE | K19: CTEC NOTI DOCU IMOP JBFI KKMP PREC | L19: TBTR | M19: 46153 | N19: 46153 | O19: VTORR010 | P19: CMEND008 | Q19: 46153 | R19: 46149 | S19: 46153 | T19: 46151 | U19: 46154 | X19: 267.18 | Y19: 267.18
A20: C81 | B20: NP | C20: 035 | D20: 30038014 | E20: 110511155 | F20: C81 | G20: Reparación Línea Acelerador Silo N°2 | H20: CGSTMRMM | I20: CHSS-SU-PHC-SAL-SIL02-STR | J20: SISTEMA DE TRANSPORTE AIRE ACELERADORES | K20: CTEC NOTI DOCU IMOP JBFI KKMP PREC | L20: TRAT | M20: 46153 | N20: 46153 | O20: MJAIM002 | P20: CMEND008 | Q20: 46153 | R20: 46152 | S20: 46153 | T20: 46153 | U20: 46153 | X20: 0.04 | Y20: 0.04
A21: C81 | B21: NP | C21: 035 | D21: 30040812 | E21: 110513930 | F21: C81 | G21: Destapar línea 3" BBA Aurora a C.Prod.MT | H21: CGSTMRMM | I21: CHSS-SU-PHC-MMV-BBAPA | J21: BOMBA POZO AURORA 20 | K21: CTEC NOTI DOCU IMOP JBFI KKMP PREC | L21: TBTR | M21: 46153 | N21: 46153 | O21: MJAIM002 | P21: CMEND008 | Q21: 46154 | R21: 46153 | S21: 46153 | T21: 46153 | U21: 46153 | X21: 89.08 | Y21: 89.08
A22: C81 | B22: NP | C22: 035 | D22: 30038033 | E22: 110515568 | F22: C81 | G22: Posición de válvula ON/OFF | H22: CGSTMRMM | I22: CHSS-SU-CTS-PVS-PVS01 | J22: PLANTA VAPOR SOBRANTE Nº 1 | K22: CTEC NOTI DOCU IMOP JBFI KKMP PREC | L22: TBTR | M22: 46153 | N22: 46153 | O22: JGALL059 | P22: CMEND008 | Q22: 46153 | R22: 46153 | S22: 46153 | T22: 46153 | U22: 46153 | X22: 89.06 | Y22: 89.06
A23: C81 | B23: PL | C23: 025 | D23: 28578642 | E23: 109098395 | F23: C81 | G23: Cambio filtros de admisión C-2 | H23: CGSTMRMM | I23: CHSS-SU-CTS-A90-COS02 | J23: COMPRESOR CENTRIFUGO ELLIOTT 02 | K23: LIB. NOTI DOCU IMOP JBFI MACO MOVM PREC* | L23: TBTR | M23: 46154 | N23: 46154 | O23: TRAMI002 | P23: MJAIM002 | Q23: 45700 | R23: 45700 | S23: 46154 | T23: 46154 | U23: 46159 | X23: 7582.67 | Y23: 7920.56
A24: C81 | B24: PL | C24: 025 | D24: 28653763 | E24: 109171579 | F24: C81 | G24: Cambio de bba enfriadera C-1 CTS | H24: CGSTMRMM | I24: CHSS-SU-CTS-A90-COS01 | J24: COMPRESOR CENTRIFUGO ELLIOTT 01 | K24: LIB. NOTI DOCU IMOP JBFI MACO MOVM PREC* | L24: TBTR | M24: 46154 | N24: 46154 | O24: TRAMI002 | P24: MJAIM002 | Q24: 45722 | R24: 45722 | S24: 46154 | T24: 46154 | U24: 46159 | X24: 3369.76 | Y24: 3369.76
A25: C81 | B25: PL | C25: 025 | D25: 29226605 | E25: 109726769 | F25: C81 | G25: Reemplazo panel de control compresor 20 | H25: CGSTMRMM | I25: CHSS-SU-CTS-A30-CAP20-INS | J25: SISTEMA DE CONTROL Y AUTOMATIZACION | K25: LIB. NOTI DOCU IMOP JBFI MACO MOVM PREC* | L25: TRAT | M25: 46154 | N25: 46155 | O25: TRAMI002 | P25: MREINES | Q25: 45897 | R25: 45897 | S25: 46154 | T25: 46154 | U25: 46156 | X25: 156217.08 | Y25: 156217.08
A26: C81 | B26: PL | C26: 010 | D26: 29956151 | E26: 110432883 | F26: C81 | G26: MRT 1S MEC LIMPIEZA MOLINO HARDINGE 2 | H26: CGSTMRMM | I26: CHSS-SU-PHC-MMH-MLH02 | J26: MOLINO HARDINGE Nº2 | K26: CTEC NOTI DOCU IMOP JBFI KKMP PREC PROG | L26: TRAT | M26: 46154 | N26: 46154 | O26: IP1020260414 | P26: CMEND008 | Q26: 46145 | R26: 46126 | S26: 46154 | T26: 46154 | U26: 46154 | V26: 139517 | W26: 251836 | X26: 89.11 | Y26: 89.11
A27: C81 | B27: PL | C27: 010 | D27: 29956161 | E27: 110432893 | F27: C81 | G27: MRT 1S MTTO CORREA 129 | H27: CGSTMRMM | I27: CHSS-SU-PHC-TCH-CT129 | J27: CORREA TRANSPORTADORA Nº129 | K27: CTEC NOTI DOCU IMOP JBFI KKMP PREC PROG | L27: TRAT | M27: 46154 | N27: 46154 | O27: IP1020260414 | P27: CMEND008 | Q27: 46145 | R27: 46126 | S27: 46154 | T27: 46154 | U27: 46154 | V27: 225688 | W27: 419099 | X27: 267.35 | Y27: 267.35
A28: C82 | B28: PL | C28: 020 | D28: 29963525 | E28: 110439864 | F28: C82 | G28: INSPECCION SISTEMA SAPCI S/E CHUQUICAMAT | H28: CGSSERME | I28: CHSS-SE-SUP-SPA-SUBCH-SAP | J28: SISTEMA SAPCI S/E CHUQUICAMATA | K28: CTEC NOTI DOCU IMOP JBFI KKMP PREC PROG | L28: TBTR | M28: 46154 | N28: 46154 | O28: IP1020260416 | P28: CURQU002 | Q28: 46139 | R28: 46128 | S28: 46154 | T28: 46154 | U28: 46154 | V28: 226517 | W28: 419564 | X28: 82.4 | Y28: 82.4
A29: C82 | B29: PL | C29: 020 | D29: 29963526 | E29: 110439865 | F29: C82 | G29: INSPECCION SISTEMA SAPCI S/E SUB-A | H29: CGSSERME | I29: CHSS-SE-SUP-SPA-SUBEA-SAP | J29: SISTEMA SAPCI S/E SUB-A | K29: CTEC NOTI DOCU IMOP JBFI KKMP PREC PROG | L29: TBTR | M29: 46154 | N29: 46154 | O29: IP1020260416 | P29: CURQU002 | Q29: 46139 | R29: 46128 | S29: 46154 | T29: 46154 | U29: 46154 | V29: 226518 | W29: 419825 | X29: 82.4 | Y29: 82.4
A30: C81 | B30: PL | C30: 010 | D30: 29971630 | E30: 110447996 | F30: C81 | G30: MRT 3S MEC MTTO ANÁLISIS VIBRACIONES PHC | H30: CGSTMRMM | I30: CHSS-SU-PHC-INS | J30: INSTALACIONES INDUSTRIALES PLANTA CAL | K30: LIB. NOTP DOCU IMOP KKMP PREC PROG | L30: TRAT | M30: 46154 | N30: 46155 | O30: IP1020260420 | P30: LVEGA028 | Q30: 46145 | R30: 46132 | S30: 46154 | T30: 46154 | V30: 225365 | W30: 418362 | X30: 0.13 | Y30: 0.19
A31: C81 | B31: PL | C31: 010 | D31: 29971633 | E31: 110447999 | F31: C81 | G31: MRT 4S MTTO MEC CAJON BOMBAS MT | H31: CGSTMRMM | I31: CHSS-SU-PHC-MMV-CJMLN | J31: CAJON CICLON MOLINO TORRE | K31: CTEC NOTI DOCU IMOP JBFI KKMP PREC PROG | L31: TBTR | M31: 46154 | N31: 46154 | O31: IP1020260420 | P31: CMEND008 | Q31: 46145 | R31: 46132 | S31: 46154 | T31: 46154 | U31: 46154 | V31: 225400 | W31: 418490 | X31: 178.27 | Y31: 178.27
A32: C82 | B32: PL | C32: 020 | D32: 29983459 | E32: 110459257 | F32: C82 | G32: Insp. 4M S/E Dist. 13.8 kV Fundición | H32: CGSSERME | I32: CDEE-SED | J32: SUBESTACIONES DE DISTRIBUCION | K32: CTEC NOTI DOCU IMOP JBFI KKMP PREC PROG | L32: TBTR | M32: 46154 | N32: 46155 | O32: IP1020260423 | P32: JGALA017 | Q32: 46139 | R32: 46135 | S32: 46154 | T32: 46154 | U32: 46154 | V32: 165529 | W32: 299283 | X32: 1812.8 | Y32: 1812.8
A33: C81 | B33: PL | C33: 010 | D33: 29993326 | E33: 110468682 | F33: C81 | G33: MRT 4S MEC INSP SOPLADOR N°6 | H33: CGSTMRMM | I33: CHSS-SU-CTS-A20-SOP06 | J33: SOPLADOR INGERSOL RAND Nº 6 | K33: CTEC NOTI DOCU IMOP JBFI KKMP PREC PROG | L33: TBTR | M33: 46154 | N33: 46155 | O33: IP1020260427 | P33: CMEND008 | Q33: 46145 | R33: 46139 | S33: 46154 | T33: 46155 | U33: 46156 | V33: 223637 | W33: 414908 | X33: 2422.57 | Y33: 2422.57
A34: C81 | B34: NP | C34: 035 | D34: 30037701 | E34: 110513921 | F34: C81 | G34: Puerta lado sur Correa Aux. No cierra | H34: CGSTMRMM | I34: CHSS-SU-PHC-TCH-CAUMH | J34: CORREA AUXILIAR MOLINOS HARDINGE | K34: CTEC NOTI DOCU IMOP JBFI KKMP PREC | L34: TRAT | M34: 46154 | N34: 46154 | O34: MJAIM002 | P34: CMEND008 | Q34: 46154 | R34: 46153 | S34: 46154 | T34: 46153 | U34: 46153 | X34: 0.02 | Y34: 0.02
A35: C81 | B35: NP | C35: 035 | D35: 30035711 | E35: 110516455 | F35: C81 | G35: chequeo alinemiento pots PES | H35: CGSTMRMM | I35: CHSS-SU-CTS-ENF-BCPV1 | J35: BOMBA CIRCULADORA 1 VAPOR SOBRANTE | K35: CTEC NOTI DOCU IMOP JBFI KKMP PREC | L35: TBTR | M35: 46154 | N35: 46154 | O35: MCHAV005 | P35: CMEND008 | Q35: 46154 | R35: 46154 | S35: 46154 | T35: 46154 | U35: 46155 | X35: 623.42 | Y35: 623.42
A36: C81 | B36: NP | C36: 035 | D36: 30042812 | E36: 110518096 | F36: C81 | G36: Ducto entrada filtros mangas pernos suel | H36: CGSTMRMM | I36: CHSS-SU-PHC-SAL-SIL02-FIL | J36: FILTRO DE MANGA | K36: CTEC NOTI DOCU IMOP JBFI KKMP PREC | L36: TRAT | M36: 46154 | N36: 46154 | O36: MJAIM002 | P36: CMEND008 | Q36: 46154 | R36: 46154 | S36: 46154 | T36: 46154 | U36: 46154 | X36: 0.02 | Y36: 0.02
A37: C81 | B37: NP | C37: 035 | D37: 30042780 | E37: 110518097 | F37: C81 | G37: Cambio válvula 1" cajón trómel MH2 | H37: CGSTMRMM | I37: CHSS-SU-PHC-MMH-MLH02 | J37: MOLINO HARDINGE Nº2 | K37: CTEC NOTI DOCU IMOP JBFI KKMP PREC | L37: TRAT | M37: 46154 | N37: 46154 | O37: MJAIM002 | P37: CMEND008 | Q37: 46154 | R37: 46154 | S37: 46154 | T37: 46154 | U37: 46154 | X37: 0.02 | Y37: 0.02
A38: C82 | B38: NP | C38: 030 | D38: 30045218 | E38: 110518476 | F38: C82 | G38: Med. Desc. parciales Enlace T7-123 SE 10 | H38: CGSSERME | I38: CDEE-SEP-S10-PAT | J38: PATIO SUBESTACION 10 | K38: CTEC NOTI DOCU FCAP IMOP JBFI KKMP PREC | L38: TBTR | M38: 46154 | N38: 46154 | O38: ICUEV002 | P38: JGALA017 | Q38: 46154 | R38: 46154 | S38: 46154 | T38: 46154 | U38: 46154 | X38: 164.8 | Y38: 164.8
A39: C82 | B39: PL | C39: 010 | D39: 28605719 | E39: 109124261 | F39: C82 | G39: LAVADO DE AISLADORES LINEA 12 | H39: CGSSERME | I39: CDEE-LIN-L12-100 | J39: LINEA Nº12 | K39: CTEC NOTI DOCU IMOP JBFI KKMP PREC PROG | L39: TBTR | M39: 46155 | N39: 46157 | O39: JCARR068 | P39: CURQU002 | Q39: 46147 | R39: 45713 | S39: 46155 | T39: 46155 | U39: 46159 | V39: 21398 | W39: 38839 | X39: 0.64 | Y39: 0.64
A40: C81 | B40: PL | C40: 025 | D40: 28714656 | E40: 109229554 | F40: C81 | G40: Normalización de líneas agua/aire/aceite | H40: CGSTMRMM | I40: CHSS-SU-CTS-A90-COS13 | J40: COMPRESOR CENTRIFUGO ELLIOTT 13 | K40: LIB. NOTI DOCU IMOP JBFI MACO MOVM PREC* | L40: TBTR | M40: 46155 | N40: 46155 | O40: TRAMI002 | P40: MJAIM002 | Q40: 45743 | R40: 45741 | S40: 46155 | T40: 46155 | U40: 46159 | X40: 850.64 | Y40: 928.57
...

Sheet Tabla
A1: Avisos Pendientes
A2: Proceso | B2: Gr.Planif | C2: Gr.planif.PM | D2: Avisos
A3: 02 SUMINISTRO ELECTRICO DCH | B3: C82 | C3: Pl.Dist.Energ.Elec | D3: 7
A4: Total general | D4: 7
A7: Órdenes Pendientes
A8: Proceso | B8: Gr. Planif | C8: Gr.planif.PM | D8: Órdenes
A9: 03 PLANTAS DE SUMINISTROS DCH | B9: C81 | C9: Pl.Termoelec.Chuq. | D9: 5
A10: 99 ESENCIALES INFRA. SERV. DCH | B10: C71 | C10: Pl.Maestranza.Cent | D10: 2
B11: C82 | C11: Pl.Dist.Energ.Elec | D11: 4
A12: 01 INFRAESTRUC CONC DCH | B12: C71 | C12: Pl.Maestranza.Cent | D12: 5
B13: C84 | C13: Pl.Tall.Electr.Cen | D13: 1
B14: C72 | C14: Pl.Calderería.Cent | D14: 3
A15: 02 SUMINISTRO ELECTRICO DCH | B15: C82 | C15: Pl.Dist.Energ.Elec | D15: 9
A16: Total general | D16: 29
A19: % Trabajo Planificado
A20: Suma de HH Totales Reales | D20: Criterio
A21: Proceso | B21: Gr. planif | C21: Gr. planif.PM | D21: Planificado | E21: Sin HR | F21: Imprevistos | G21: Total general | H21: Cumplimiento
A22: 02 SUMINISTRO ELECTRICO DCH | B22: C82 | C22: Pl.Dist.Energ.Elec | D22: 463 | F22: 10 | G22: 473 | H22: =D22/G22 -> 0.97885835
A23: 03 PLANTAS DE SUMINISTROS DCH | B23: C81 | C23: Pl.Termoelec.Chuq. | D23: 756.1 | E23: 14 | F23: 47.5 | G23: 817.6 | H23: =D23/G23 -> 0.92477984
A24: 99 ESENCIALES INFRA. SERV. DCH | B24: C82 | C24: Pl.Dist.Energ.Elec | D24: 56 | G24: 56 | H24: =D24/G24 -> 1
B25: C81 | C25: Pl.Termoelec.Chuq. | D25: 29.5 | G25: 29.5 | H25: =D25/G25 -> 1
A26: 01 INFRAESTRUC CONC DCH | B26: CO2 | C26: Concentradora A2 | F26: 70 | G26: 70 | H26: =D26/G26 -> 0
A27: Total general | D27: 1304.6 | E27: 14 | F27: 127.5 | G27: 1446.1 | H27: =D27/G27 -> 0.90215061
A30: Programa Semanal
A31: Suma de Total Op. Programadas | D31: Criterio
A32: Proceso | B32: Gr.planif | C32: Gr.planif.PM | D32: Cumple | E32: No Cumple | F32: Total general | G32: % Cumplimiento
A33: 02 SUMINISTRO ELECTRICO DCH | B33: C82 | C33: Pl.Dist.Energ.Elec | D33: 42 | E33: 15 | F33: 57 | G33: =D33/F33 -> 0.73684211
A34: 03 PLANTAS DE SUMINISTROS DCH | B34: C81 | C34: Pl.Termoelec.Chuq. | D34: 244 | E34: 41 | F34: 285 | G34: 0.8807
A35: 99 ESENCIALES INFRA. SERV. DCH | B35: C82 | C35: Pl.Dist.Energ.Elec | D35: 16 | F35: 16 | G35: =D35/F35 -> 1
B36: C81 | C36: Pl.Termoelec.Chuq. | D36: 13 | E36: 20 | F36: 33 | G36: =D36/F36 -> 0.39393939
A37: Total general | D37: 315 | E37: 76 | F37: 391 | G37: 0.8235
A40: Plan Matriz
A41: Suma de Cantidad de Operaciones totales | D41: Criterio
A42: Proceso | B42: Gr.planif | C42: Gr.planif.PM | D42: Cumple | E42: No Cumple | F42: Total general | G42: % Cumplimiento
A43: 02 SUMINISTRO ELECTRICO DCH | B43: C82 | C43: Pl.Dist.Energ.Elec | D43: 12 | E43: 20 | F43: 32 | G43: =D43/F43 -> 0.375
A44: 03 PLANTAS DE SUMINISTROS DCH | B44: C81 | C44: Pl.Termoelec.Chuq. | D44: 154 | E44: 46 | F44: 200 | G44: 0.935
A45: 99 ESENCIALES INFRA. SERV. DCH | B45: C82 | C45: Pl.Dist.Energ.Elec | D45: 16 | F45: 16 | G45: =D45/F45 -> 1
B46: C81 | C46: Pl.Termoelec.Chuq. | D46: 2 | F46: 2 | G46: =D46/F46 -> 1
B47: C71 | C47: Pl.Maestranza.Cent | E47: 27 | F47: 27 | G47: =D47/F47 -> 0
A48: Total general | D48: 184 | E48: 93 | F48: 277 | G48: 0.7834

Sheet Avisos Pendientes
A1: Año natural/Semana | B1: Fase | C1: Proceso | D1: SubProceso | E1: Aviso | F1: Txt. Breve | G1: Clase de aviso | H1: Prioridad | I1: Status de Sistema | J1: Fecha Aviso PM | K1: Gr.planif.PM | L1: Gr.Planif | M1: Orden mantenimiento | N1: Columna3 | O1: Puesto de trabajo | P1: Pto. Trabajo | Q1: Número de avisos pendientes
A2: 18.2026 | B2: 08 INFR SERVIC Y SUMIN DCH | C2: 02 SUMINISTRO ELECTRICO DCH | D2: CDEE | E2: 29998837 | F2: Descargar Printout Celdas 34.5KV Tchitak | G2: M1 | H2: 3 | I2: DOCU MEAB | J2: 46140 | K2: Pl.Dist.Energ.Elec | L2: C82 | M2: # | N2: Sin asignar | O2: MANT & PLANIF SUMINISTRO ELECTRICO | P2: CGSSERME | Q2: 1
A3: 18.2026 | B3: 08 INFR SERVIC Y SUMIN DCH | C3: 02 SUMINISTRO ELECTRICO DCH | D3: CDEE | E3: 30001811 | F3: EJE IMAGEN TERMICA DE DEFECTUOSO TR14 | G3: M1 | H3: 3 | I3: DOCU MEAB | J3: 46140 | K3: Pl.Dist.Energ.Elec | L3: C82 | M3: # | N3: Sin asignar | O3: MANT & PLANIF SUMINISTRO ELECTRICO | P3: CGSSERME | Q3: 1
A4: 18.2026 | B4: 08 INFR SERVIC Y SUMIN DCH | C4: 02 SUMINISTRO ELECTRICO DCH | D4: CDEE | E4: 30007775 | F4: Ejec: ATR 2 SE Chuquicamata 220/100 KV | G4: M1 | H4: 3 | I4: DOCU MEAB | J4: 46142 | K4: Pl.Dist.Energ.Elec | L4: C82 | M4: # | N4: Sin asignar | O4: MANT & PLANIF SUMINISTRO ELECTRICO | P4: CGSSERME | Q4: 1
A5: 18.2026 | B5: 08 INFR SERVIC Y SUMIN DCH | C5: 02 SUMINISTRO ELECTRICO DCH | D5: CDEE | E5: 30013617 | F5: STNcierre perimetral y accesos bloqueado | G5: M1 | H5: 3 | I5: DOCU MEAB | J5: 46145 | K5: Pl.Dist.Energ.Elec | L5: C82 | M5: # | N5: Sin asignar | O5: MANT & PLANIF SUMINISTRO ELECTRICO | P5: CGSSERME | Q5: 1
A6: 18.2026 | B6: 08 INFR SERVIC Y SUMIN DCH | C6: 02 SUMINISTRO ELECTRICO DCH | D6: CDEE | E6: 30013618 | F6: rep. de fugas de aceite en unit. 25-A | G6: M1 | H6: 2 | I6: DOCU MEAB | J6: 46145 | K6: Pl.Dist.Energ.Elec | L6: C82 | M6: # | N6: Sin asignar | O6: MANT & PLANIF SUMINISTRO ELECTRICO | P6: CGSSERME | Q6: 1
A7: 18.2026 | B7: 08 INFR SERVIC Y SUMIN DCH | C7: 02 SUMINISTRO ELECTRICO DCH | D7: CHSS-SE | E7: 30012249 | F7: cambio presostato acoplador de barra | G7: M1 | H7: 3 | I7: DOCU MEAB | J7: 46144 | K7: Pl.Dist.Energ.Elec | L7: C82 | M7: # | N7: Sin asignar | O7: MANT & PLANIF SUMINISTRO ELECTRICO | P7: CGSSERME | Q7: 1
A8: 18.2026 | B8: 08 INFR SERVIC Y SUMIN DCH | C8: 02 SUMINISTRO ELECTRICO DCH | D8: # | E8: 30011912 | F8: Fab. de tablero de control motores TR5-b | G8: M1 | H8: 3 | I8: MEAB | J8: 46144 | K8: Pl.Dist.Energ.Elec | L8: C82 | M8: # | N8: Sin asignar | O8: MANT & PLANIF SUMINISTRO ELECTRICO | P8: CGSSERME | Q8: 1
A9: Resultado total | Q9: 7

Sheet Órdenes Pendientes
A1: Gr.planif.PM | B1: Gr. Planif | C1: Fase | D1: Proceso | E1: Sub-Proceso | F1: Orden mantenimiento | G1: Txt. Breve | H1: Status de Sistema | I1: Clase de orden | J1: Clase actividad PM | K1: Actividad PM | L1: Año natural/Semana | M1: Pto. Trabajo | N1: Puesto de trabajo | O1: Número de OT Pendientes
A2: Pl.Termoelec.Chuq. | B2: C81 | C2: 08 INFR SERVIC Y SUMIN DCH | D2: 03 PLANTAS DE SUMINISTROS DCH | E2: CHSS-SU | F2: 109500285 | G2: CAMBIO BBA 3B - FILTRACION | H2: LIB. NOTP DOCU IMOP MACO MOVM PREC PROG | I2: PL | J2: Correctivo Planificado | K2: 025 | L2: 17.2026 | M2: MANT & PLANIF CENTRAL TERMICA SULFUROS | N2: CGSTMRMM | O2: 1
A3: Pl.Termoelec.Chuq. | B3: C81 | C3: 08 INFR SERVIC Y SUMIN DCH | D3: 03 PLANTAS DE SUMINISTROS DCH | E3: CHSS-SU | F3: 109500289 | G3: CAMBIO BBA 3C - FILTRACION | H3: LIB. NOTP DOCU IMOP MACO MOVM PREC PROG | I3: PL | J3: Correctivo Planificado | K3: 025 | L3: 17.2026 | M3: MANT & PLANIF CENTRAL TERMICA SULFUROS | N3: CGSTMRMM | O3: 1
A4: Pl.Termoelec.Chuq. | B4: C81 | C4: 08 INFR SERVIC Y SUMIN DCH | D4: 03 PLANTAS DE SUMINISTROS DCH | E4: CHSS-SU | F4: 109501785 | G4: CAMBIO BBA 1B - FILTRACION SELLOS | H4: LIB. NOTP DOCU IMOP MACO PREC PROG TRAT | I4: PL | J4: Correctivo Planificado | K4: 025 | L4: 16.2026 | M4: MANT & PLANIF CENTRAL TERMICA SULFUROS | N4: CGSTMRMM | O4: 1
A5: Pl.Termoelec.Chuq. | B5: C81 | C5: 08 INFR SERVIC Y SUMIN DCH | D5: 03 PLANTAS DE SUMINISTROS DCH | E5: CHSS-SU | F5: 109654371 | G5: FUCO26 Cambio Tubo nivel Des Caldera 3 | H5: LIB. NOTI IMOP JBFI MACO MOVM PREC PROG | I5: PL | J5: Correctivo Planificado | K5: 025 | L5: 17.2026 | M5: MANT & PLANIF CENTRAL TERMICA SULFUROS | N5: CGSTMRMM | O5: 1
A6: Pl.Termoelec.Chuq. | B6: C81 | C6: 08 INFR SERVIC Y SUMIN DCH | D6: 03 PLANTAS DE SUMINISTROS DCH | E6: CHSS-SU | F6: 110011685 | G6: CTR FILTROS DE CARTUCHOS SATURADOS-MALOS | H6: LIB. IMOP MACO MOVM PREC PROG TRAT | I6: PL | J6: Correctivo Planificado | K6: 025 | L6: 11.2026 | M6: MANT & PLANIF CENTRAL TERMICA SULFUROS | N6: CGSTMRMM | O6: 1
A7: Pl.Tall.Electr.Cen | B7: C84 | C7: 08 INFR SERVIC Y SUMIN DCH | D7: 01 INFRAESTRUC CONC DCH | E7: # | F7: 110454096 | G7: 22-5523 200HP 4160V 290RPM FLA | H7: LIB. IMOP KKMP MOVM PREC TRAT | I7: ST | J7: Reparación | K7: 060 | L7: 17.2026 | M7: MANT & PLANIF. TALLER ELECTRICO CENTRAL | N7: CGSSERTE | O7: 1
A8: Pl.Maestranza.Cent | B8: C71 | C8: 08 INFR SERVIC Y SUMIN DCH | D8: 01 INFRAESTRUC CONC DCH | E8: # | F8: 110150639 | G8: Rectificar placa base piñón BM | H8: LIB. IMOP KKMP PREC TRAT | I8: ST | J8: Reparación | K8: 060 | L8: 17.2026 | M8: SERVICIO INTERNO MAESTRANZA | N8: CGSSTM02 | O8: 1
A9: Pl.Maestranza.Cent | B9: C71 | C9: 08 INFR SERVIC Y SUMIN DCH | D9: 01 INFRAESTRUC CONC DCH | E9: # | F9: 110304391 | G9: perforar pillow block piñón mobos 18 | H9: LIB. IMOP KKMP PREC TRAT | I9: ST | J9: Modificación | K9: 050 | L9: 17.2026 | M9: SERVICIO INTERNO MAESTRANZA | N9: CGSSTM02 | O9: 1
A10: Pl.Maestranza.Cent | B10: C71 | C10: 08 INFR SERVIC Y SUMIN DCH | D10: 01 INFRAESTRUC CONC DCH | E10: # | F10: 110304394 | G10: rebajar base pillow block piñón sag-18 | H10: LIB. IMOP KKMP PREC TRAT | I10: ST | J10: Modificación | K10: 050 | L10: 17.2026 | M10: SERVICIO INTERNO MAESTRANZA | N10: CGSSTM02 | O10: 1
A11: Pl.Maestranza.Cent | B11: C71 | C11: 08 INFR SERVIC Y SUMIN DCH | D11: 01 INFRAESTRUC CONC DCH | E11: # | F11: 110304610 | G11: mecanizar acoplamiento reductor feeder | H11: LIB. IMOP KKMP PREC TRAT | I11: ST | J11: Reparación | K11: 060 | L11: 17.2026 | M11: SERVICIO INTERNO MAESTRANZA | N11: CGSSTM02 | O11: 1
A12: Pl.Maestranza.Cent | B12: C71 | C12: 08 INFR SERVIC Y SUMIN DCH | D12: 01 INFRAESTRUC CONC DCH | E12: # | F12: 110304611 | G12: ensamblado de rueda tripeer | H12: LIB. IMOP KKMP PREC TRAT | I12: ST | J12: Reparación | K12: 060 | L12: 17.2026 | M12: SERVICIO INTERNO MAESTRANZA | N12: CGSSTM02 | O12: 1
A13: Pl.Maestranza.Cent | B13: C71 | C13: 08 INFR SERVIC Y SUMIN DCH | D13: 99 ESENCIALES INFRA. SERV. DCH | E13: 02 GRUAS INFRA DCH | F13: 110379900 | G13: MRT 4S MEC MTTO PUENTE GRUA | H13: LIB. NOTI IMOP JBFI KKMP PREC PROG TBTR | I13: PL | J13: Preventivo Sistemático | K13: 010 | L13: 18.2026 | M13: SERVICIO INTERNO MAESTRANZA | N13: CGSSTM02 | O13: 1
... A30: Pl.Calderería.Cent | B30: C72 | C30: 08 INFR SERVIC Y SUMIN DCH | D30: 01 INFRAESTRUC CONC DCH | E30: # | F30: 110387265 | G30: CAMBIO CORAZA POSTE SH N°10104410 | H30: LIB. NOTP IMOP KKMP PREC PROG TRAT | I30: ST | J30: Reparación | K30: 060 | L30: 17.2026 | M30: SERVICIO INTERNO CALDERERIA | N30: CGSSTM03 | O30: 1
A31: Resultado total | O31: 29

Sheet % Trabajo Planificado
A1: Año natural/Semana | B1: Fase | C1: Proceso | D1: SubProceso | E1: Puesto de trabajo | F1: Psto. Trabaj | G1: Clase actividad PM | H1: Actividad PM | I1: Gr. planif | J1: Gr. planif.PM | K1: Orden mantenimiento | L1: Txt. Breve | M1: Status de Sistema | N1: Clase de orden | O1: Horizonte | P1: Fecha Libera Orden | Q1: Fecha inicio real | R1: Grupo hojas de ruta | S1: % Planificado (HH) | T1: HH Plan. Reales | U1: HH Totales Reales | V1: Criterio
A2: 20.2026 | B2: 08 INFR SERVIC Y SUMIN DCH | C2: 01 INFRAESTRUC CONC DCH | D2: # | E2: MANT & PLANIF ELEC CONC MOLIENDA A2 A3 | F2: CCOAXRME | G2: 030 | H2: Emergencia | I2: =VLOOKUP(Tbl_PctTrabajoPlanificado[[#This Row],[Orden mantenimiento]],Data!$E$2:$G$101,2,FALSE) -> CO2 | J2: {=_xlfn.IFS(I2="C81","Pl.Termoelec.Chuq.",I2="C82","Pl.Dist.Energ.Elec",I2="C89","Pl.Mant.Ind.Electr",I2="CO0","Concentradora A0",I2="CO1","Concentradora A1",I2="CO2","Concentradora A2",I2="CB1","SAE Centralizado",I2="C71","Pl.Maestranza.Cent",I2="C72","Pl.Calderería.Cent",I2="C74","CONTRATOS METALMEC",I2="C40","Planif. Refinería",I2="SAPCI","SAPCI",TRUE,"Código no encontrado")} -> Concentradora A2 | K2: 110527601 | L2: REPARACION CTO ENCHUFES GCON | M2: NOTI JBFI LIB. NLIQ PWF RESA | N2: NP | O2: =Tbl_PctTrabajoPlanificado[[#This Row],[Fecha inicio real]]-Tbl_PctTrabajoPlanificado[[#This Row],[Fecha Libera Orden]] -> 0 | P2: 46157 | Q2: 46157 | R2: # | U2: 70 | V2: Imprevistos
A3: 20.2026 | B3: 08 INFR SERVIC Y SUMIN DCH | C3: 02 SUMINISTRO ELECTRICO DCH | D3: CDEE | E3: MANT & PLANIF SUMINISTRO ELECTRICO | F3: CGSSERME | G3: 010 | H3: Preventivo Sistemático | I3: =VLOOKUP(Tbl_PctTrabajoPlanificado[[#This Row],[Orden mantenimiento]],Data!$E$2:$G$101,2,FALSE) -> C82 | J3: {=_xlfn.IFS(I3="C81","Pl.Termoelec.Chuq.",I3="C82","Pl.Dist.Energ.Elec",I3="C89","Pl.Mant.Ind.Electr",I3="CO0","Concentradora A0",I3="CO1","Concentradora A1",I3="CO2","Concentradora A2",I3="CB1","SAE Centralizado",I3="C71","Pl.Maestranza.Cent",I3="C72","Pl.Calderería.Cent",I3="C74","CONTRATOS METALMEC",I3="C40","Planif. Refinería",I3="SAPCI","SAPCI",TRUE,"Código no encontrado")} -> Pl.Dist.Energ.Elec | K3: 109124261 | L3: LAVADO DE AISLADORES LINEA 12 | M3: NOTI CTEC JBFI NLIQ PWF RESA PLAN | N3: PL | O3: =Tbl_PctTrabajoPlanificado[[#This Row],[Fecha inicio real]]-Tbl_PctTrabajoPlanificado[[#This Row],[Fecha Libera Orden]] -> 8 | P3: 46147 | Q3: 46155 | R3: 97142 | S3: 100 | T3: 22 | U3: 22 | V3: Planificado
A4: 20.2026 | B4: 08 INFR SERVIC Y SUMIN DCH | C4: 02 SUMINISTRO ELECTRICO DCH | D4: CDEE | E4: MANT & PLANIF SUMINISTRO ELECTRICO | F4: CGSSERME | G4: 010 | H4: Preventivo Sistemático | I4: =VLOOKUP(Tbl_PctTrabajoPlanificado[[#This Row],[Orden mantenimiento]],Data!$E$2:$G$101,2,FALSE) -> C82 | J4: {=_xlfn.IFS(I4="C81","Pl.Termoelec.Chuq.",I4="C82","Pl.Dist.Energ.Elec",I4="C89","Pl.Mant.Ind.Electr",I4="CO0","Concentradora A0",I4="CO1","Concentradora A1",I4="CO2","Concentradora A2",I4="CB1","SAE Centralizado",I4="C71","Pl.Maestranza.Cent",I4="C72","Pl.Calderería.Cent",I4="C74","CONTRATOS METALMEC",I4="C40","Planif. Refinería",I4="SAPCI","SAPCI",TRUE,"Código no encontrado")} -> Pl.Dist.Energ.Elec | K4: 109124261 | L4: LAVADO DE AISLADORES LINEA 12 | M4: NOTI CTEC JBFI NLIQ PWF RESA PLAN | N4: PL | O4: =Tbl_PctTrabajoPlanificado[[#This Row],[Fecha inicio real]]-Tbl_PctTrabajoPlanificado[[#This Row],[Fecha Libera Orden]] -> 9 | P4: 46147 | Q4: 46156 | R4: 97142 | S4: 100 | T4: 22 | U4: 22 | V4: Planificado
A5: 20.2026 | B5: 08 INFR SERVIC Y SUMIN DCH | C5: 02 SUMINISTRO ELECTRICO DCH | D5: CDEE | E5: MANT & PLANIF SUMINISTRO ELECTRICO | F5: CGSSERME | G5: 010 | H5: Preventivo Sistemático | I5: =VLOOKUP(Tbl_PctTrabajoPlanificado[[#This Row],[Orden mantenimiento]],Data!$E$2:$G$101,2,FALSE) -> C82 | J5: {=_xlfn.IFS(I5="C81","Pl.Termoelec.Chuq.",I5="C82","Pl.Dist.Energ.Elec",I5="C89","Pl.Mant.Ind.Electr",I5="CO0","Concentradora A0",I5="CO1","Concentradora A1",I5="CO2","Concentradora A2",I5="CB1","SAE Centralizado",I5="C71","Pl.Maestranza.Cent",I5="C72","Pl.Calderería.Cent",I5="C74","CONTRATOS METALMEC",I5="C40","Planif. Refinería",I5="SAPCI","SAPCI",TRUE,"Código no encontrado")} -> Pl.Dist.Energ.Elec | K5: 109124261 | L5: LAVADO DE AISLADORES LINEA 12 | M5: NOTI CTEC JBFI NLIQ PWF RESA PLAN | N5: PL | O5: =Tbl_PctTrabajoPlanificado[[#This Row],[Fecha inicio real]]-Tbl_PctTrabajoPlanificado[[#This Row],[Fecha Libera Orden]] -> 10 | P5: 46147 | Q5: 46157 | R5: 97142 | S5: 100 | T5: 20 | U5: 20 | V5: Planificado
A6: 20.2026 | B6: 08 INFR SERVIC Y SUMIN DCH | C6: 02 SUMINISTRO ELECTRICO DCH | D6: CDEE | E6: MANT & PLANIF SUMINISTRO ELECTRICO | F6: CGSSERME | G6: 010 | H6: Preventivo Sistemático | I6: =VLOOKUP(Tbl_PctTrabajoPlanificado[[#This Row],[Orden mantenimiento]],Data!$E$2:$G$101,2,FALSE) -> C82 | J6: {=_xlfn.IFS(I6="C81","Pl.Termoelec.Chuq.",I6="C82","Pl.Dist.Energ.Elec",I6="C89","Pl.Mant.Ind.Electr",I6="CO0","Concentradora A0",I6="CO1","Concentradora A1",I6="CO2","Concentradora A2",I6="CB1","SAE Centralizado",I6="C71","Pl.Maestranza.Cent",I6="C72","Pl.Calderería.Cent",I6="C74","CONTRATOS METALMEC",I6="C40","Planif. Refinería",I6="SAPCI","SAPCI",TRUE,"Código no encontrado")} -> Pl.Dist.Energ.Elec | K6: 110443469 | L6: INSPECCION MT CHANCADO PRIMARIO PTMP | M6: NOTI CTEC JBFI NLIQ PWF RESA PLAN | N6: PL | O6: =Tbl_PctTrabajoPlanificado[[#This Row],[Fecha inicio real]]-Tbl_PctTrabajoPlanificado[[#This Row],[Fecha Libera Orden]] -> 11 | P6: 46146 | Q6: 46157 | R6: 10371 | S6: 100 | T6: 44 | U6: 44 | V6: Planificado
A7: 20.2026 | B7: 08 INFR SERVIC Y SUMIN DCH | C7: 02 SUMINISTRO ELECTRICO DCH | D7: CDEE | E7: MANT & PLANIF SUMINISTRO ELECTRICO | F7: CGSSERME | G7: 020 | H7: Preventivo Predictivo | I7: =VLOOKUP(Tbl_PctTrabajoPlanificado[[#This Row],[Orden mantenimiento]],Data!$E$2:$G$101,2,FALSE) -> C82 | J7: {=_xlfn.IFS(I7="C81","Pl.Termoelec.Chuq.",I7="C82","Pl.Dist.Energ.Elec",I7="C89","Pl.Mant.Ind.Electr",I7="CO0","Concentradora A0",I7="CO1","Concentradora A1",I7="CO2","Concentradora A2",I7="CB1","SAE Centralizado",I7="C71","Pl.Maestranza.Cent",I7="C72","Pl.Calderería.Cent",I7="C74","CONTRATOS METALMEC",I7="C40","Planif. Refinería",I7="SAPCI","SAPCI",TRUE,"Código no encontrado")} -> Pl.Dist.Energ.Elec | K7: 110330383 | L7: Insp. 4M S/E Dist. 13.8 kV Refinería | M7: NOTI CTEC JBFI NLIQ PWF RESA PLAN | N7: PL | O7: =Tbl_PctTrabajoPlanificado[[#This Row],[Fecha inicio real]]-Tbl_PctTrabajoPlanificado[[#This Row],[Fecha Libera Orden]] -> 14 | P7: 46139 | Q7: 46153 | R7: 35977 | S7: 100 | T7: 44 | U7: 44 | V7: Planificado
A8: 20.2026 | B8: 08 INFR SERVIC Y SUMIN DCH | C8: 02 SUMINISTRO ELECTRICO DCH | D8: CDEE | E8: MANT & PLANIF SUMINISTRO ELECTRICO | F8: CGSSERME | G8: 020 | H8: Preventivo Predictivo | I8: =VLOOKUP(Tbl_PctTrabajoPlanificado[[#This Row],[Orden mantenimiento]],Data!$E$2:$G$101,2,FALSE) -> C82 | J8: {=_xlfn.IFS(I8="C81","Pl.Termoelec.Chuq.",I8="C82","Pl.Dist.Energ.Elec",I8="C89","Pl.Mant.Ind.Electr",I8="CO0","Concentradora A0",I8="CO1","Concentradora A1",I8="CO2","Concentradora A2",I8="CB1","SAE Centralizado",I8="C71","Pl.Maestranza.Cent",I8="C72","Pl.Calderería.Cent",I8="C74","CONTRATOS METALMEC",I8="C40","Planif. Refinería",I8="SAPCI","SAPCI",TRUE,"Código no encontrado")} -> Pl.Dist.Energ.Elec | K8: 110459257 | L8: Insp. 4M S/E Dist. 13.8 kV Fundición | M8: NOTI CTEC JBFI NLIQ PWF PLAN | N8: PL | O8: =Tbl_PctTrabajoPlanificado[[#This Row],[Fecha inicio real]]-Tbl_PctTrabajoPlanificado[[#This Row],[Fecha Libera Orden]] -> 15 | P8: 46139 | Q8: 46154 | R8: 35977 | S8: 100 | T8: 44 | U8: 44 | V8: Planificado
A9: 20.2026 | B9: 08 INFR SERVIC Y SUMIN DCH | C9: 02 SUMINISTRO ELECTRICO DCH | D9: CDEE | E9: MANT & PLANIF SUMINISTRO ELECTRICO | F9: CGSSERME | G9: 025 | H9: Correctivo Planificado | I9: =VLOOKUP(Tbl_PctTrabajoPlanificado[[#This Row],[Orden mantenimiento]],Data!$E$2:$G$101,2,FALSE) -> C82 | J9: {=_xlfn.IFS(I9="C81","Pl.Termoelec.Chuq.",I9="C82","Pl.Dist.Energ.Elec",I9="C89","Pl.Mant.Ind.Electr",I9="CO0","Concentradora A0",I9="CO1","Concentradora A1",I9="CO2","Concentradora A2",I9="CB1","SAE Centralizado",I9="C71","Pl.Maestranza.Cent",I9="C72","Pl.Calderería.Cent",I9="C74","CONTRATOS METALMEC",I9="C40","Planif. Refinería",I9="SAPCI","SAPCI",TRUE,"Código no encontrado")} -> Pl.Dist.Energ.Elec | K9: 110377744 | L9: Revis. y repar. Comp aire 52HT18 S/E A | M9: NOTI CTEC JBFI NLIQ PWF RESA PLAN | N9: PL | O9: =Tbl_PctTrabajoPlanificado[[#This Row],[Fecha inicio real]]-Tbl_PctTrabajoPlanificado[[#This Row],[Fecha Libera Orden]] -> 10 | P9: 46148 | Q9: 46158 | R9: 26780 | S9: 100 | T9: 44 | U9: 44 | V9: Planificado
A10: 20.2026 | B10: 08 INFR SERVIC Y SUMIN DCH | C10: 02 SUMINISTRO ELECTRICO DCH | D10: CDEE | E10: MANT & PLANIF SUMINISTRO ELECTRICO | F10: CGSSERME | G10: 025 | H10: Correctivo Planificado | I10: =VLOOKUP(Tbl_PctTrabajoPlanificado[[#This Row],[Orden mantenimiento]],Data!$E$2:$G$101,2,FALSE) -> C82 | J10: {=_xlfn.IFS(I10="C81","Pl.Termoelec.Chuq.",I10="C82","Pl.Dist.Energ.Elec",I10="C89","Pl.Mant.Ind.Electr",I10="CO0","Concentradora A0",I10="CO1","Concentradora A1",I10="CO2","Concentradora A2",I10="CB1","SAE Centralizado",I10="C71","Pl.Maestranza.Cent",I10="C72","Pl.Calderería.Cent",I10="C74","CONTRATOS METALMEC",I10="C40","Planif. Refinería",I10="SAPCI","SAPCI",TRUE,"Código no encontrado")} -> Pl.Dist.Energ.Elec | K10: 110474160 | L10: EJE. CAMBIO RASA CELDA K13 S/E 10A | M10: NOTI CTEC JBFI NLIQ PWF RESA PLAN | N10: PL | O10: =Tbl_PctTrabajoPlanificado[[#This Row],[Fecha inicio real]]-Tbl_PctTrabajoPlanificado[[#This Row],[Fecha Libera Orden]] -> 8 | P10: 46148 | Q10: 46156 | R10: 56673 | S10: 100 | T10: 101 | U10: 101 | V10: Planificado
A11: 20.2026 | B11: 08 INFR SERVIC Y SUMIN DCH | C11: 02 SUMINISTRO ELECTRICO DCH | D11: CDEE | E11: MANT & PLANIF SUMINISTRO ELECTRICO | F11: CGSSERME | G11: 025 | H11: Correctivo Planificado | I11: =VLOOKUP(Tbl_PctTrabajoPlanificado[[#This Row],[Orden mantenimiento]],Data!$E$2:$G$101,2,FALSE) -> C82 | J11: {=_xlfn.IFS(I11="C81","Pl.Termoelec.Chuq.",I11="C82","Pl.Dist.Energ.Elec",I11="C89","Pl.Mant.Ind.Electr",I11="CO0","Concentradora A0",I11="CO1","Concentradora A1",I11="CO2","Concentradora A2",I11="CB1","SAE Centralizado",I11="C71","Pl.Maestranza.Cent",I11="C72","Pl.Calderería.Cent",I11="C74","CONTRATOS METALMEC",I11="C40","Planif. Refinería",I11="SAPCI","SAPCI",TRUE,"Código no encontrado")} -> Pl.Dist.Energ.Elec | K11: 110496644 | L11: STN MTTO SIST RESPALDO S/E PRINCIPAL CAL | M11: NOTI CTEC JBFI NLIQ PWF RESA PLAN | N11: PL | O11: =Tbl_PctTrabajoPlanificado[[#This Row],[Fecha inicio real]]-Tbl_PctTrabajoPlanificado[[#This Row],[Fecha Libera Orden]] -> 9 | P11: 46147 | Q11: 46156 | R11: 98949 | S11: 100 | T11: 15 | U11: 15 | V11: Planificado
A12: 20.2026 | B12: 08 INFR SERVIC Y SUMIN DCH | C12: 02 SUMINISTRO ELECTRICO DCH | D12: CDEE | E12: MANT & PLANIF SUMINISTRO ELECTRICO | F12: CGSSERME | G12: 030 | H12: Emergencia | I12: =VLOOKUP(Tbl_PctTrabajoPlanificado[[#This Row],[Orden mantenimiento]],Data!$E$2:$G$101,2,FALSE) -> C82 | J12: {=_xlfn.IFS(I12="C81","Pl.Termoelec.Chuq.",I12="C82","Pl.Dist.Energ.Elec",I12="C89","Pl.Mant.Ind.Electr",I12="CO0","Concentradora A0",I12="CO1","Concentradora A1",I12="CO2","Concentradora A2",I12="CB1","SAE Centralizado",I12="C71","Pl.Maestranza.Cent",I12="C72","Pl.Calderería.Cent",I12="C74","CONTRATOS METALMEC",I12="C40","Planif. Refinería",I12="SAPCI","SAPCI",TRUE,"Código no encontrado")} -> Pl.Dist.Energ.Elec | K12: 110518476 | L12: Med. Desc. parciales Enlace T7-123 SE 10 | M12: NOTI CTEC JBFI NLIQ PWF RESA | N12: NP | O12: =Tbl_PctTrabajoPlanificado[[#This Row],[Fecha inicio real]]-Tbl_PctTrabajoPlanificado[[#This Row],[Fecha Libera Orden]] -> 0 | P12: 46154 | Q12: 46154 | R12: # | U12: 4 | V12: Imprevistos
A13: 20.2026 | B13: 08 INFR SERVIC Y SUMIN DCH | C13: 02 SUMINISTRO ELECTRICO DCH | D13: CHSS-SE | E13: MANT & PLANIF SUMINISTRO ELECTRICO | F13: CGSSERME | G13: 010 | H13: Preventivo Sistemático | I13: =VLOOKUP(Tbl_PctTrabajoPlanificado[[#This Row],[Orden mantenimiento]],Data!$E$2:$G$101,2,FALSE) -> C82 | J13: {=_xlfn.IFS(I13="C81","Pl.Termoelec.Chuq.",I13="C82","Pl.Dist.Energ.Elec",I13="C89","Pl.Mant.Ind.Electr",I13="CO0","Concentradora A0",I13="CO1","Concentradora A1",I13="CO2","Concentradora A2",I13="CB1","SAE Centralizado",I13="C71","Pl.Maestranza.Cent",I13="C72","Pl.Calderería.Cent",I13="C74","CONTRATOS METALMEC",I13="C40","Planif. Refinería",I13="SAPCI","SAPCI",TRUE,"Código no encontrado")} -> Pl.Dist.Energ.Elec | K13: 110439645 | L13: Inspección 2M S/E Sopladores | M13: NOTI CTEC JBFI NLIQ PWF RESA PLAN | N13: PL | O13: =Tbl_PctTrabajoPlanificado[[#This Row],[Fecha inicio real]]-Tbl_PctTrabajoPlanificado[[#This Row],[Fecha Libera Orden]] -> 18 | P13: 46139 | Q13: 46157 | R13: 56856 | S13: 100 | T13: 24 | U13: 24 | V13: Planificado
A14: 20.2026 | B14: 08 INFR SERVIC Y SUMIN DCH | C14: 02 SUMINISTRO ELECTRICO DCH | D14: CHSS-SE | E14: MANT & PLANIF SUMINISTRO ELECTRICO | F14: CGSSERME | G14: 010 | H14: Preventivo Sistemático | I14: =VLOOKUP(Tbl_PctTrabajoPlanificado[[#This Row],[Orden mantenimiento]],Data!$E$2:$G$101,2,FALSE) -> C82 | J14: {=_xlfn.IFS(I14="C81","Pl.Termoelec.Chuq.",I14="C82","Pl.Dist.Energ.Elec",I14="C89","Pl.Mant.Ind.Electr",I14="CO0","Concentradora A0",I14="CO1","Concentradora A1",I14="CO2","Concentradora A2",I14="CB1","SAE Centralizado",I14="C71","Pl.Maestranza.Cent",I14="C72","Pl.Calderería.Cent",I14="C74","CONTRATOS METALMEC",I14="C40","Planif. Refinería",I14="SAPCI","SAPCI",TRUE,"Código no encontrado")} -> Pl.Dist.Energ.Elec | K14: 110439646 | L14: Inspección 2M S/E K-1 | M14: NOTI CTEC JBFI NLIQ PWF RESA PLAN | N14: PL | O14: =Tbl_PctTrabajoPlanificado[[#This Row],[Fecha inicio real]]-Tbl_PctTrabajoPlanificado[[#This Row],[Fecha Libera Orden]] -> 19 | P14: 46139 | Q14: 46158 | R14: 56856 | S14: 100 | T14: 24 | U14: 24 | V14: Planificado
A15: 20.2026 | B15: 08 INFR SERVIC Y SUMIN DCH | C15: 02 SUMINISTRO ELECTRICO DCH | D15: CHSS-SE | E15: MANT & PLANIF SUMINISTRO ELECTRICO | F15: CGSSERME | G15: 010 | H15: Preventivo Sistemático | I15: =VLOOKUP(Tbl_PctTrabajoPlanificado[[#This Row],[Orden mantenimiento]],Data!$E$2:$G$101,2,FALSE) -> C82 | J15: {=_xlfn.IFS(I15="C81","Pl.Termoelec.Chuq.",I15="C82","Pl.Dist.Energ.Elec",I15="C89","Pl.Mant.Ind.Electr",I15="CO0","Concentradora A0",I15="CO1","Concentradora A1",I15="CO2","Concentradora A2",I15="CB1","SAE Centralizado",I15="C71","Pl.Maestranza.Cent",I15="C72","Pl.Calderería.Cent",I15="C74","CONTRATOS METALMEC",I15="C40","Planif. Refinería",I15="SAPCI","SAPCI",TRUE,"Código no encontrado")} -> Pl.Dist.Energ.Elec | K15: 110439647 | L15: Termografía 2M S/E Sopladores | M15: NOTI CTEC JBFI NLIQ PWF RESA PLAN | N15: PL | O15: =Tbl_PctTrabajoPlanificado[[#This Row],[Fecha inicio real]]-Tbl_PctTrabajoPlanificado[[#This Row],[Fecha Libera Orden]] -> 18 | P15: 46139 | Q15: 46157 | R15: 25012 | S15: 100 | T15: 6 | U15: 6 | V15: Planificado
A16: 20.2026 | B16: 08 INFR SERVIC Y SUMIN DCH | C16: 02 SUMINISTRO ELECTRICO DCH | D16: CHSS-SE | E16: MANT & PLANIF SUMINISTRO ELECTRICO | F16: CGSSERME | G16: 010 | H16: Preventivo Sistemático | I16: =VLOOKUP(Tbl_PctTrabajoPlanificado[[#This Row],[Orden mantenimiento]],Data!$E$2:$G$101,2,FALSE) -> C82 | J16: {=_xlfn.IFS(I16="C81","Pl.Termoelec.Chuq.",I16="C82","Pl.Dist.Energ.Elec",I16="C89","Pl.Mant.Ind.Electr",I16="CO0","Concentradora A0",I16="CO1","Concentradora A1",I16="CO2","Concentradora A2",I16="CB1","SAE Centralizado",I16="C71","Pl.Maestranza.Cent",I16="C72","Pl.Calderería.Cent",I16="C74","CONTRATOS METALMEC",I16="C40","Planif. Refinería",I16="SAPCI","SAPCI",TRUE,"Código no encontrado")} -> Pl.Dist.Energ.Elec | K16: 110439648 | L16: Termografía 2M S/E K-1 | M16: NOTI CTEC JBFI NLIQ PWF RESA PLAN | N16: PL | O16: =Tbl_PctTrabajoPlanificado[[#This Row],[Fecha inicio real]]-Tbl_PctTrabajoPlanificado[[#This Row],[Fecha Libera Orden]] -> 19 | P16: 46139 | Q16: 46158 | R16: 25012 | S16: 100 | T16: 6 | U16: 6 | V16: Planificado
A17: 20.2026 | B17: 08 INFR SERVIC Y SUMIN DCH | C17: 02 SUMINISTRO ELECTRICO DCH | D17: CHSS-SE | E17: MANT & PLANIF SUMINISTRO ELECTRICO | F17: CGSSERME | G17: 020 | H17: Preventivo Predictivo | I17: =VLOOKUP(Tbl_PctTrabajoPlanificado[[#This Row],[Orden mantenimiento]],Data!$E$2:$G$101,2,FALSE) -> C82 | J17: {=_xlfn.IFS(I17="C81","Pl.Termoelec.Chuq.",I17="C82","Pl.Dist.Energ.Elec",I17="C89","Pl.Mant.Ind.Electr",I17="CO0","Concentradora A0",I17="CO1","Concentradora A1",I17="CO2","Concentradora A2",I17="CB1","SAE Centralizado",I17="C71","Pl.Maestranza.Cent",I17="C72","Pl.Calderería.Cent",I17="C74","CONTRATOS METALMEC",I17="C40","Planif. Refinería",I17="SAPCI","SAPCI",TRUE,"Código no encontrado")} -> Pl.Dist.Energ.Elec | K17: 110427496 | L17: MED.DESCARGAS PARCIALES S/E TCHITACk TR2 | M17: NOTI CTEC JBFI NLIQ PWF RESA PLAN | N17: PL | O17: =Tbl_PctTrabajoPlanificado[[#This Row],[Fecha inicio real]]-Tbl_PctTrabajoPlanificado[[#This Row],[Fecha Libera Orden]] -> 13 | P17: 46146 | Q17: 46159 | R17: 18845 | S17: 100 | T17: 4 | U17: 4 | V17: Planificado
A18: 20.2026 | B18: 08 INFR SERVIC Y SUMIN DCH | C18: 02 SUMINISTRO ELECTRICO DCH | D18: CHSS-SE | E18: MANT & PLANIF SUMINISTRO ELECTRICO | F18: CGSSERME | G18: 020 | H18: Preventivo Predictivo | I18: =VLOOKUP(Tbl_PctTrabajoPlanificado[[#This Row],[Orden mantenimiento]],Data!$E$2:$G$101,2,FALSE) -> C82 | J18: {=_xlfn.IFS(I18="C81","Pl.Termoelec.Chuq.",I18="C82","Pl.Dist.Energ.Elec",I18="C89","Pl.Mant.Ind.Electr",I18="CO0","Concentradora A0",I18="CO1","Concentradora A1",I18="CO2","Concentradora A2",I18="CB1","SAE Centralizado",I18="C71","Pl.Maestranza.Cent",I18="C72","Pl.Calderería.Cent",I18="C74","CONTRATOS METALMEC",I18="C40","Planif. Refinería",I18="SAPCI","SAPCI",TRUE,"Código no encontrado")} -> Pl.Dist.Energ.Elec | K18: 110443695 | L18: MEDICIÓN DESCARGAS PARCIALES ATR2 | M18: NOTI CTEC JBFI NLIQ PWF RESA PLAN | N18: PL | O18: =Tbl_PctTrabajoPlanificado[[#This Row],[Fecha inicio real]]-Tbl_PctTrabajoPlanificado[[#This Row],[Fecha Libera Orden]] -> 13 | P18: 46146 | Q18: 46159 | R18: 18845 | S18: 100 | T18: 9 | U18: 9 | V18: Planificado
A19: 20.2026 | B19: 08 INFR SERVIC Y SUMIN DCH | C19: 02 SUMINISTRO ELECTRICO DCH | D19: CHSS-SE | E19: MANT & PLANIF SUMINISTRO ELECTRICO | F19: CGSSERME | G19: 020 | H19: Preventivo Predictivo | I19: =VLOOKUP(Tbl_PctTrabajoPlanificado[[#This Row],[Orden mantenimiento]],Data!$E$2:$G$101,2,FALSE) -> C82 | J19: {=_xlfn.IFS(I19="C81","Pl.Termoelec.Chuq.",I19="C82","Pl.Dist.Energ.Elec",I19="C89","Pl.Mant.Ind.Electr",I19="CO0","Concentradora A0",I19="CO1","Concentradora A1",I19="CO2","Concentradora A2",I19="CB1","SAE Centralizado",I19="C71","Pl.Maestranza.Cent",I19="C72","Pl.Calderería.Cent",I19="C74","CONTRATOS METALMEC",I19="C40","Planif. Refinería",I19="SAPCI","SAPCI",TRUE,"Código no encontrado")} -> Pl.Dist.Energ.Elec | K19: 110473175 | L19: TOMA MUESTRA ACEITE S/E CHUQUICAMAT ATR1 | M19: NOTI CTEC JBFI NLIQ PWF RESA PLAN | N19: PL | O19: =Tbl_PctTrabajoPlanificado[[#This Row],[Fecha inicio real]]-Tbl_PctTrabajoPlanificado[[#This Row],[Fecha Libera Orden]] -> 19 | P19: 46140 | Q19: 46159 | R19: 98013 | S19: 100 | T19: 4 | U19: 4 | V19: Planificado
A20: 20.2026 | B20: 08 INFR SERVIC Y SUMIN DCH | C20: 02 SUMINISTRO ELECTRICO DCH | D20: CHSS-SE | E20: MANT & PLANIF SUMINISTRO ELECTRICO | F20: CGSSERME | G20: 020 | H20: Preventivo Predictivo | I20: =VLOOKUP(Tbl_PctTrabajoPlanificado[[#This Row],[Orden mantenimiento]],Data!$E$2:$G$101,2,FALSE) -> C82 | J20: {=_xlfn.IFS(I20="C81","Pl.Termoelec.Chuq.",I20="C82","Pl.Dist.Energ.Elec",I20="C89","Pl.Mant.Ind.Electr",I20="CO0","Concentradora A0",I20="CO1","Concentradora A1",I20="CO2","Concentradora A2",I20="CB1","SAE Centralizado",I20="C71","Pl.Maestranza.Cent",I20="C72","Pl.Calderería.Cent",I20="C74","CONTRATOS METALMEC",I20="C40","Planif. Refinería",I20="SAPCI","SAPCI",TRUE,"Código no encontrado")} -> Pl.Dist.Energ.Elec | K20: 110486153 | L20: TOMA MUESTRA ACEITE S/E TCHITACK TR2 | M20: NOTI CTEC JBFI NLIQ PWF RESA PLAN | N20: PL | O20: =Tbl_PctTrabajoPlanificado[[#This Row],[Fecha inicio real]]-Tbl_PctTrabajoPlanificado[[#This Row],[Fecha Libera Orden]] -> 13 | P20: 46146 | Q20: 46159 | R20: 98013 | S20: 100 | T20: 4 | U20: 4 | V20: Planificado
A21: 20.2026 | B21: 08 INFR SERVIC Y SUMIN DCH | C21: 02 SUMINISTRO ELECTRICO DCH | D21: CHSS-SE | E21: MANT & PLANIF SUMINISTRO ELECTRICO | F21: CGSSERME | G21: 020 | H21: Preventivo Predictivo | I21: =VLOOKUP(Tbl_PctTrabajoPlanificado[[#This Row],[Orden mantenimiento]],Data!$E$2:$G$101,2,FALSE) -> C82 | J21: {=_xlfn.IFS(I21="C81","Pl.Termoelec.Chuq.",I21="C82","Pl.Dist.Energ.Elec",I21="C89","Pl.Mant.Ind.Electr",I21="CO0","Concentradora A0",I21="CO1","Concentradora A1",I21="CO2","Concentradora A2",I21="CB1","SAE Centralizado",I21="C71","Pl.Maestranza.Cent",I21="C72","Pl.Calderería.Cent",I21="C74","CONTRATOS METALMEC",I21="C40","Planif. Refinería",I21="SAPCI","SAPCI",TRUE,"Código no encontrado")} -> Pl.Dist.Energ.Elec | K21: 110494994 | L21: TOMA MUESTRA ACEITE S/E TCHITACK TR1 | M21: NOTI CTEC JBFI NLIQ PWF RESA PLAN | N21: PL | O21: =Tbl_PctTrabajoPlanificado[[#This Row],[Fecha inicio real]]-Tbl_PctTrabajoPlanificado[[#This Row],[Fecha Libera Orden]] -> 11 | P21: 46148 | Q21: 46159 | R21: 98013 | S21: 100 | T21: 4 | U21: 4 | V21: Planificado
A22: 20.2026 | B22: 08 INFR SERVIC Y SUMIN DCH | C22: 02 SUMINISTRO ELECTRICO DCH | D22: CHSS-SE | E22: MANT & PLANIF SUMINISTRO ELECTRICO | F22: CGSSERME | G22: 025 | H22: Correctivo Planificado | I22: =VLOOKUP(Tbl_PctTrabajoPlanificado[[#This Row],[Orden mantenimiento]],Data!$E$2:$G$101,2,FALSE) -> C82 | J22: {=_xlfn.IFS(I22="C81","Pl.Termoelec.Chuq.",I22="C82","Pl.Dist.Energ.Elec",I22="C89","Pl.Mant.Ind.Electr",I22="CO0","Concentradora A0",I22="CO1","Concentradora A1",I22="CO2","Concentradora A2",I22="CB1","SAE Centralizado",I22="C71","Pl.Maestranza.Cent",I22="C72","Pl.Calderería.Cent",I22="C74","CONTRATOS METALMEC",I22="C40","Planif. Refinería",I22="SAPCI","SAPCI",TRUE,"Código no encontrado")} -> Pl.Dist.Energ.Elec | K22: 110304324 | L22: Toma Mstra Aceite EquCrít 2°Sem T7A SE10 | M22: NOTI CTEC JBFI NLIQ PWF RESA PLAN | N22: PL | O22: =Tbl_PctTrabajoPlanificado[[#This Row],[Fecha inicio real]]-Tbl_PctTrabajoPlanificado[[#This Row],[Fecha Libera Orden]] -> 11 | P22: 46148 | Q22: 46159 | R22: 75545 | S22: 100 | T22: 22 | U22: 22 | V22: Planificado
A23: 20.2026 | B23: 08 INFR SERVIC Y SUMIN DCH | C23: 02 SUMINISTRO ELECTRICO DCH | D23: CHSS-SE | E23: MANT & PLANIF SUMINISTRO ELECTRICO | F23: CGSSERME | G23: 035 | H23: Correctivo No Planificado | I23: =VLOOKUP(Tbl_PctTrabajoPlanificado[[#This Row],[Orden mantenimiento]],Data!$E$2:$G$101,2,FALSE) -> C82 | J23: {=_xlfn.IFS(I23="C81","Pl.Termoelec.Chuq.",I23="C82","Pl.Dist.Energ.Elec",I23="C89","Pl.Mant.Ind.Electr",I23="CO0","Concentradora A0",I23="CO1","Concentradora A1",I23="CO2","Concentradora A2",I23="CB1","SAE Centralizado",I23="C71","Pl.Maestranza.Cent",I23="C72","Pl.Calderería.Cent",I23="C74","CONTRATOS METALMEC",I23="C40","Planif. Refinería",I23="SAPCI","SAPCI",TRUE,"Código no encontrado")} -> Pl.Dist.Energ.Elec | K23: 110526034 | L23: RELLENO SF6 L12 GIS 100 KV SE CHUQUI | M23: NOTI CTEC JBFI NLIQ PWF RESA | N23: NP | O23: =Tbl_PctTrabajoPlanificado[[#This Row],[Fecha inicio real]]-Tbl_PctTrabajoPlanificado[[#This Row],[Fecha Libera Orden]] -> -1 | P23: 46157 | Q23: 46156 | R23: # | U23: 6 | V23: Imprevistos
A24: 20.2026 | B24: 08 INFR SERVIC Y SUMIN DCH | C24: 03 PLANTAS DE SUMINISTROS DCH | D24: CHSS-SU | E24: MANT & PLANIF CENTRAL TERMICA SULFUROS | F24: CGSTMRMM | G24: 010 | H24: Preventivo Sistemático | I24: =VLOOKUP(Tbl_PctTrabajoPlanificado[[#This Row],[Orden mantenimiento]],Data!$E$2:$G$101,2,FALSE) -> C81 | J24: {=_xlfn.IFS(I24="C81","Pl.Termoelec.Chuq.",I24="C82","Pl.Dist.Energ.Elec",I24="C89","Pl.Mant.Ind.Electr",I24="CO0","Concentradora A0",I24="CO1","Concentradora A1",I24="CO2","Concentradora A2",I24="CB1","SAE Centralizado",I24="C71","Pl.Maestranza.Cent",I24="C72","Pl.Calderería.Cent",I24="C74","CONTRATOS METALMEC",I24="C40","Planif. Refinería",I24="SAPCI","SAPCI",TRUE,"Código no encontrado")} -> Pl.Termoelec.Chuq. | K24: 110288268 | L24: MRT 12S MEC MTTO CALDERA N°2 | M24: NOTI CTEC JBFI NLIQ PWF RESA PLAN | N24: PL | O24: =Tbl_PctTrabajoPlanificado[[#This Row],[Fecha inicio real]]-Tbl_PctTrabajoPlanificado[[#This Row],[Fecha Libera Orden]] -> 10 | P24: 46145 | Q24: 46155 | R24: 99105 | S24: 100 | T24: 1 | U24: 1 | V24: Planificado
A25: 20.2026 | B25: 08 INFR SERVIC Y SUMIN DCH | C25: 03 PLANTAS DE SUMINISTROS DCH | D25: CHSS-SU | E25: MANT & PLANIF CENTRAL TERMICA SULFUROS | F25: CGSTMRMM | G25: 010 | H25: Preventivo Sistemático | I25: =VLOOKUP(Tbl_PctTrabajoPlanificado[[#This Row],[Orden mantenimiento]],Data!$E$2:$G$101,2,FALSE) -> C81 | J25: {=_xlfn.IFS(I25="C81","Pl.Termoelec.Chuq.",I25="C82","Pl.Dist.Energ.Elec",I25="C89","Pl.Mant.Ind.Electr",I25="CO0","Concentradora A0",I25="CO1","Concentradora A1",I25="CO2","Concentradora A2",I25="CB1","SAE Centralizado",I25="C71","Pl.Maestranza.Cent",I25="C72","Pl.Calderería.Cent",I25="C74","CONTRATOS METALMEC",I25="C40","Planif. Refinería",I25="SAPCI","SAPCI",TRUE,"Código no encontrado")} -> Pl.Termoelec.Chuq. | K25: 110288268 | L25: MRT 12S MEC MTTO CALDERA N°2 | M25: NOTI CTEC JBFI NLIQ PWF RESA PLAN | N25: PL | O25: =Tbl_PctTrabajoPlanificado[[#This Row],[Fecha inicio real]]-Tbl_PctTrabajoPlanificado[[#This Row],[Fecha Libera Orden]] -> 14 | P25: 46145 | Q25: 46159 | R25: 99105 | S25: 100 | T25: 1.2 | U25: 1.2 | V25: Planificado
A26: 20.2026 | B26: 08 INFR SERVIC Y SUMIN DCH | C26: 03 PLANTAS DE SUMINISTROS DCH | D26: CHSS-SU | E26: MANT & PLANIF CENTRAL TERMICA SULFUROS | F26: CGSTMRMM | G26: 010 | H26: Preventivo Sistemático | I26: =VLOOKUP(Tbl_PctTrabajoPlanificado[[#This Row],[Orden mantenimiento]],Data!$E$2:$G$101,2,FALSE) -> C81 | J26: {=_xlfn.IFS(I26="C81","Pl.Termoelec.Chuq.",I26="C82","Pl.Dist.Energ.Elec",I26="C89","Pl.Mant.Ind.Electr",I26="CO0","Concentradora A0",I26="CO1","Concentradora A1",I26="CO2","Concentradora A2",I26="CB1","SAE Centralizado",I26="C71","Pl.Maestranza.Cent",I26="C72","Pl.Calderería.Cent",I26="C74","CONTRATOS METALMEC",I26="C40","Planif. Refinería",I26="SAPCI","SAPCI",TRUE,"Código no encontrado")} -> Pl.Termoelec.Chuq. | K26: 110288268 | L26: MRT 12S MEC MTTO CALDERA N°2 | M26: NOTI CTEC JBFI NLIQ PWF PLAN | N26: PL | O26: =Tbl_PctTrabajoPlanificado[[#This Row],[Fecha inicio real]]-Tbl_PctTrabajoPlanificado[[#This Row],[Fecha Libera Orden]] -> 14 | P26: 46145 | Q26: 46159 | R26: 99105 | S26: 100 | T26: 13.5 | U26: 13.5 | V26: Planificado
A27: 20.2026 | B27: 08 INFR SERVIC Y SUMIN DCH | C27: 03 PLANTAS DE SUMINISTROS DCH | D27: CHSS-SU | E27: MANT & PLANIF CENTRAL TERMICA SULFUROS | F27: CGSTMRMM | G27: 010 | H27: Preventivo Sistemático | I27: =VLOOKUP(Tbl_PctTrabajoPlanificado[[#This Row],[Orden mantenimiento]],Data!$E$2:$G$101,2,FALSE) -> C81 | J27: {=_xlfn.IFS(I27="C81","Pl.Termoelec.Chuq.",I27="C82","Pl.Dist.Energ.Elec",I27="C89","Pl.Mant.Ind.Electr",I27="CO0","Concentradora A0",I27="CO1","Concentradora A1",I27="CO2","Concentradora A2",I27="CB1","SAE Centralizado",I27="C71","Pl.Maestranza.Cent",I27="C72","Pl.Calderería.Cent",I27="C74","CONTRATOS METALMEC",I27="C40","Planif. Refinería",I27="SAPCI","SAPCI",TRUE,"Código no encontrado")} -> Pl.Termoelec.Chuq. | K27: 110406270 | L27: MRT 4S MEC TOMA MUESTRA ACEITE S20 | M27: NOTI CTEC JBFI NLIQ PWF RESA PLAN | N27: PL | O27: =Tbl_PctTrabajoPlanificado[[#This Row],[Fecha inicio real]]-Tbl_PctTrabajoPlanificado[[#This Row],[Fecha Libera Orden]] -> 13 | P27: 46145 | Q27: 46158 | R27: 92589 | S27: 100 | T27: 2.6 | U27: 2.6 | V27: Planificado
A28: 20.2026 | B28: 08 INFR SERVIC Y SUMIN DCH | C28: 03 PLANTAS DE SUMINISTROS DCH | D28: CHSS-SU | E28: MANT & PLANIF CENTRAL TERMICA SULFUROS | F28: CGSTMRMM | G28: 010 | H28: Preventivo Sistemático | I28: =VLOOKUP(Tbl_PctTrabajoPlanificado[[#This Row],[Orden mantenimiento]],Data!$E$2:$G$101,2,FALSE) -> C81 | J28: {=_xlfn.IFS(I28="C81","Pl.Termoelec.Chuq.",I28="C82","Pl.Dist.Energ.Elec",I28="C89","Pl.Mant.Ind.Electr",I28="CO0","Concentradora A0",I28="CO1","Concentradora A1",I28="CO2","Concentradora A2",I28="CB1","SAE Centralizado",I28="C71","Pl.Maestranza.Cent",I28="C72","Pl.Calderería.Cent",I28="C74","CONTRATOS METALMEC",I28="C40","Planif. Refinería",I28="SAPCI","SAPCI",TRUE,"Código no encontrado")} -> Pl.Termoelec.Chuq. | K28: 110406276 | L28: MRT 4S LIMPIEZA CANALA EXTERIOR | M28: NOTI CTEC JBFI NLIQ PWF RESA PLAN | N28: PL | O28: =Tbl_PctTrabajoPlanificado[[#This Row],[Fecha inicio real]]-Tbl_PctTrabajoPlanificado[[#This Row],[Fecha Libera Orden]] -> 11 | P28: 46145 | Q28: 46156 | R28: 98139 | S28: 100 | T28: 12 | U28: 12 | V28: Planificado
A29: 20.2026 | B29: 08 INFR SERVIC Y SUMIN DCH | C29: 03 PLANTAS DE SUMINISTROS DCH | D29: CHSS-SU | E29: MANT & PLANIF CENTRAL TERMICA SULFUROS | F29: CGSTMRMM | G29: 010 | H29: Preventivo Sistemático | I29: =VLOOKUP(Tbl_PctTrabajoPlanificado[[#This Row],[Orden mantenimiento]],Data!$E$2:$G$101,2,FALSE) -> C81 | J29: {=_xlfn.IFS(I29="C81","Pl.Termoelec.Chuq.",I29="C82","Pl.Dist.Energ.Elec",I29="C89","Pl.Mant.Ind.Electr",I29="CO0","Concentradora A0",I29="CO1","Concentradora A1",I29="CO2","Concentradora A2",I29="CB1","SAE Centralizado",I29="C71","Pl.Maestranza.Cent",I29="C72","Pl.Calderería.Cent",I29="C74","CONTRATOS METALMEC",I29="C40","Planif. Refinería",I29="SAPCI","SAPCI",TRUE,"Código no encontrado")} -> Pl.Termoelec.Chuq. | K29: 110427749 | L29: MRT 4S ELEC MTTO UPS N°3 | M29: NOTI CTEC JBFI NLIQ PWF PLAN | N29: PL | O29: =Tbl_PctTrabajoPlanificado[[#This Row],[Fecha inicio real]]-Tbl_PctTrabajoPlanificado[[#This Row],[Fecha Libera Orden]] -> 10 | P29: 46145 | Q29: 46155 | R29: 98494 | S29: 100 | T29: 6 | U29: 6 | V29: Planificado
A30: 20.2026 | B30: 08 INFR SERVIC Y SUMIN DCH | C30: 03 PLANTAS DE SUMINISTROS DCH | D30: CHSS-SU | E30: MANT & PLANIF CENTRAL TERMICA SULFUROS | F30: CGSTMRMM | G30: 010 | H30: Preventivo Sistemático | I30: =VLOOKUP(Tbl_PctTrabajoPlanificado[[#This Row],[Orden mantenimiento]],Data!$E$2:$G$101,2,FALSE) -> C81 | J30: {=_xlfn.IFS(I30="C81","Pl.Termoelec.Chuq.",I30="C82","Pl.Dist.Energ.Elec",I30="C89","Pl.Mant.Ind.Electr",I30="CO0","Concentradora A0",I30="CO1","Concentradora A1",I30="CO2","Concentradora A2",I30="CB1","SAE Centralizado",I30="C71","Pl.Maestranza.Cent",I30="C72","Pl.Calderería.Cent",I30="C74","CONTRATOS METALMEC",I30="C40","Planif. Refinería",I30="SAPCI","SAPCI",TRUE,"Código no encontrado")} -> Pl.Termoelec.Chuq. | K30: 110427755 | L30: MRT 4S MTTO MEC BOMBA 2B | M30: NOTI CTEC JBFI NLIQ PWF RESA PLAN | N30: PL | O30: =Tbl_PctTrabajoPlanificado[[#This Row],[Fecha inicio real]]-Tbl_PctTrabajoPlanificado[[#This Row],[Fecha Libera Orden]] -> 11 | P30: 46145 | Q30: 46156 | R30: 98030 | S30: 100 | T30: 4 | U30: 4 | V30: Planificado
A31: 20.2026 | B31: 08 INFR SERVIC Y SUMIN DCH | C31: 03 PLANTAS DE SUMINISTROS DCH | D31: CHSS-SU | E31: MANT & PLANIF CENTRAL TERMICA SULFUROS | F31: CGSTMRMM | G31: 010 | H31: Preventivo Sistemático | I31: =VLOOKUP(Tbl_PctTrabajoPlanificado[[#This Row],[Orden mantenimiento]],Data!$E$2:$G$101,2,FALSE) -> C81 | J31: {=_xlfn.IFS(I31="C81","Pl.Termoelec.Chuq.",I31="C82","Pl.Dist.Energ.Elec",I31="C89","Pl.Mant.Ind.Electr",I31="CO0","Concentradora A0",I31="CO1","Concentradora A1",I31="CO2","Concentradora A2",I31="CB1","SAE Centralizado",I31="C71","Pl.Maestranza.Cent",I31="C72","Pl.Calderería.Cent",I31="C74","CONTRATOS METALMEC",I31="C40","Planif. Refinería",I31="SAPCI","SAPCI",TRUE,"Código no encontrado")} -> Pl.Termoelec.Chuq. | K31: 110427755 | L31: MRT 4S MTTO MEC BOMBA 2B | M31: NOTI CTEC JBFI NLIQ PWF PLAN | N31: PL | O31: =Tbl_PctTrabajoPlanificado[[#This Row],[Fecha inicio real]]-Tbl_PctTrabajoPlanificado[[#This Row],[Fecha Libera Orden]] -> 11 | P31: 46145 | Q31: 46156 | R31: 98030 | S31: 100 | T31: 1 | U31: 1 | V31: Planificado
A32: 20.2026 | B32: 08 INFR SERVIC Y SUMIN DCH | C32: 03 PLANTAS DE SUMINISTROS DCH | D32: CHSS-SU | E32: MANT & PLANIF CENTRAL TERMICA SULFUROS | F32: CGSTMRMM | G32: 010 | H32: Preventivo Sistemático | I32: =VLOOKUP(Tbl_PctTrabajoPlanificado[[#This Row],[Orden mantenimiento]],Data!$E$2:$G$101,2,FALSE) -> C81 | J32: {=_xlfn.IFS(I32="C81","Pl.Termoelec.Chuq.",I32="C82","Pl.Dist.Energ.Elec",I32="C89","Pl.Mant.Ind.Electr",I32="CO0","Concentradora A0",I32="CO1","Concentradora A1",I32="CO2","Concentradora A2",I32="CB1","SAE Centralizado",I32="C71","Pl.Maestranza.Cent",I32="C72","Pl.Calderería.Cent",I32="C74","CONTRATOS METALMEC",I32="C40","Planif. Refinería",I32="SAPCI","SAPCI",TRUE,"Código no encontrado")} -> Pl.Termoelec.Chuq. | K32: 110432882 | L32: MRT 1S MEC LIMPIEZA MOLINO HARDINGE 1 | M32: NOTI CTEC JBFI NLIQ PWF RESA PLAN | N32: PL | O32: =Tbl_PctTrabajoPlanificado[[#This Row],[Fecha inicio real]]-Tbl_PctTrabajoPlanificado[[#This Row],[Fecha Libera Orden]] -> 8 | P32: 46145 | Q32: 46153 | R32: 49861 | S32: 100 | T32: 9.4 | U32: 9.4 | V32: Planificado
